Workbook
Name _day1: '4_4_請求書'!$AZ$5
Name _day1: '4_4_納品書'!$AZ$10
Name _day1: #REF!
Name _day1: #REF!
Name _day1: #REF!
Name _day1: #REF!
Name _day2: '4_4_請求書'!$AZ$10
Name _day2: '4_4_納品書'!#REF!
Name _day2: #REF!
Name _day2: #REF!
Name _day2: #REF!
Name _day2: #REF!
Name excluded: '4_4_請求書'!#REF!
Name excluded: '4_4_納品書'!$BE$3
Name excluded: #REF!
Name excluded: #REF!
Name excluded: #REF!
Name excluded: #REF!
Name exclusive: #REF!
Name exclusive: #REF!
Name exclusive: #REF!
Name exclusive: #REF!
Name exclusive: #REF!
Name exclusive: #REF!
Name exclusive: #REF!
Name exclusive: #REF!
Name exclusive: #REF!
Name exclusive: #REF!
Name exclusive: #REF!
Name exclusive: #REF!
Name exclusive: #REF!
Name exclusive: #REF!
Name exclusive: #REF!
Name exclusive: #REF!
Name exclusive: #REF!
Name exclusive: #REF!
Name exclusive: #REF!
Name exclusive: #REF!
Name exclusive: #REF!
Name exclusive: #REF!
Name exclusive: '4_5_領収書'!$BD$5
Name exclusive: #REF!
Name exclusive: #REF!
Name exclusive: #REF!
Name exclusive: #REF!
Name exclusive: #REF!
Name exclusive: #REF!
Name exclusive: #REF!
Name exclusive: #REF!
Name exclusive: #REF!
Name exclusive: #REF!
Name exclusive: #REF!
Name exclusive: #REF!
Name exclusive: #REF!
Name exclusive: #REF!
Name exclusive: #REF!
Name exemption: '4_4_請求書'!#REF!
Name exemption: '4_4_納品書'!$BF$3
Name hutan: #REF!
Name hutan: #REF!

Sheet 管理
B1: 請求書発行者 | C1: 9 | E1: 請求日 | F1: =[1]請求書管理!$F1 -> 46097 | H1: 納品日 | I1: =[1]請求書管理!$I1 -> 46097 | K1: 領収日 | L1: =[1]請求書管理!$L1 -> 46105 | N1: お支払期限 | O1: =[1]請求書管理!$O1 -> 46105
B2: 購入者 | C2: 103 | E2: 件名： | F2: =[1]請求書管理!$F2 -> 2026年3月16日分のお取引に関するご請求書
A3: =[1]請求書管理!$A3 -> № | B3: =[1]請求書管理!$B3 -> 社名 | C3: =[1]請求書管理!$C3 -> 郵便番号 | D3: =[1]請求書管理!$D3 -> 住所1 | E3: =[1]請求書管理!$E3 -> 住所2 | F3: =[1]請求書管理!$F3 -> TEL | G3: =[1]請求書管理!$G3 -> FAX | H3: =[1]請求書管理!$H3 -> WEB | I3: =[1]請求書管理!$I3 -> 担当者 | J3: =[1]請求書管理!$J3 -> mail | K3: =[1]請求書管理!$K3 -> 登録番号 | L3: =[1]請求書管理!$L3 -> 振込先 | M3: =[1]請求書管理!$M3 -> 口座名義 | N3: =[1]請求書管理!$N3 -> お客様コード | O3: =[1]請求書管理!$O3 -> sandisk有無 | P3: =[1]請求書管理!$P3 -> sandiskURL | Q3: 請求書№ | R3: 納品書№ | S3: 領収書№
A4: =[1]請求書管理!$A4 -> 1 | B4: =[1]請求書管理!$B4 -> ダイワボウ情報システム株式会社 | C4: =[1]請求書管理!$C4 -> 530-0005 | D4: =[1]請求書管理!$D4 -> 大阪府大阪市北区中之島3丁目2番4号 | E4: =[1]請求書管理!$E4 -> 中之島フェスティバルタワー・ウエスト 10F | F4: =[1]請求書管理!$F4 -> 06-4707-8000 | G4: =[1]請求書管理!$G4 -> 06-4707-8052 | H4: =[1]請求書管理!$H4 -> https://www.pc-daiwabo.co.jp | I4: =[1]請求書管理!$I4 -> 担当事業所：東京第1支店 韋駄天事業部 | J4: =[1]請求書管理!$J4 -> mail：idaten-c@pc-daiwabo.co.jp | K4: =[1]請求書管理!$K4 -> T6120001083217 | L4: =[1]請求書管理!$L4 -> 三菱ＵＦＪ銀行 船場支店 普通 7077113 | M4: =[1]請求書管理!$M4 -> ダイワボウジョウホウシステム（カ | N4: =[1]請求書管理!$N4 -> 5824-111 | O4: =[1]請求書管理!$O4 -> ◎ | P4: =[1]請求書管理!$P4 -> https://www.pc-daiwabo.co.jp/business/maker_list_s.html | Q4: =[1]請求書管理!$Q4 -> INV-260316-101 | R4: =[1]請求書管理!$R4 -> DEL-260316-101 | S4: =[1]請求書管理!$S4 -> REC-260324-101
A5: =[1]請求書管理!$A5 -> 2 | B5: =[1]請求書管理!$B5 -> 東映無線株式会社 | C5: =[1]請求書管理!$C5 -> 101-0021 | D5: =[1]請求書管理!$D5 -> 東京都千代田区外神田1丁目10番11号 | E5: =[1]請求書管理!$E5 -> 東京ラジオデパート内 | F5: =[1]請求書管理!$F5 -> 03-3253-5660 | G5: =[1]請求書管理!$G5 -> 03-3253-5661 | H5: =[1]請求書管理!$H5 -> http://www.toeimusen.co.jp | I5: =[1]請求書管理!$I5 -> 営業部 浜田英夫 | J5: =[1]請求書管理!$J5 -> E-MAIL：th＠toeimusen.co.jp | K5: =[1]請求書管理!$K5 -> T1010001023790 | L5: =[1]請求書管理!$L5 -> 三菱ＵＦＪ銀行 神田駅前支店 当座 2025636 | M5: =[1]請求書管理!$M5 -> トウエイムセン（カ | N5: =[1]請求書管理!$N5 -> 7391-112 | O5: =[1]請求書管理!$O5 -> × | P5: =[1]請求書管理!$P5 -> 0 | Q5: =[1]請求書管理!$Q5 -> INV-260316-102 | R5: =[1]請求書管理!$R5 -> DEL-260316-102 | S5: =[1]請求書管理!$S5 -> REC-260324-102
A6: =[1]請求書管理!$A6 -> 3 | B6: =[1]請求書管理!$B6 -> 浜田電機株式会社 | C6: =[1]請求書管理!$C6 -> 103-0023 | D6: =[1]請求書管理!$D6 -> 東京都中央区日本橋本町3丁目9番4号 | E6: =[1]請求書管理!$E6 -> 0 | F6: =[1]請求書管理!$F6 -> 03-5651-7351 | G6: =[1]請求書管理!$G6 -> 03-5651-7353 | H6: =[1]請求書管理!$H6 -> https://www.hamada-dk.com | I6: =[1]請求書管理!$I6 -> 浜田 健太郎 | J6: =[1]請求書管理!$J6 -> E-MAIL：ke-hamda@hamada-dk.co.jp | K6: =[1]請求書管理!$K6 -> T6010001026302 | L6: =[1]請求書管理!$L6 -> みずほ銀行 神田支店 普通7014121 | M6: =[1]請求書管理!$M6 -> ハマダデンキ（カ | N6: =[1]請求書管理!$N6 -> 1648-113 | O6: =[1]請求書管理!$O6 -> × | P6: =[1]請求書管理!$P6 -> 0 | Q6: =[1]請求書管理!$Q6 -> INV-260316-103 | R6: =[1]請求書管理!$R6 -> DEL-260316-103 | S6: =[1]請求書管理!$S6 -> REC-260324-103
A7: =[1]請求書管理!$A7 -> 4 | B7: =[1]請求書管理!$B7 -> ウエスタンデジタル合同会社 | C7: =[1]請求書管理!$C7 -> 108-0075 | D7: =[1]請求書管理!$D7 -> 東京都港区港南1丁目6番31号 | E7: =[1]請求書管理!$E7 -> 品川東急ビル3階 | F7: =[1]請求書管理!$F7 -> 0120-893-009 | G7: =[1]請求書管理!$G7 -> 0 | H7: =[1]請求書管理!$H7 -> https://shop.sandisk.com | I7: =[1]請求書管理!$I7 -> 0 | J7: =[1]請求書管理!$J7 -> E-MAIL：westerndigital_jp@custhelp.com | K7: =[1]請求書管理!$K7 -> T2010401090562 | L7: =[1]請求書管理!$L7 -> みずほ銀行 品川支店 普通7759780 | M7: =[1]請求書管理!$M7 -> ウエスタンデジタル（ド | N7: =[1]請求書管理!$N7 -> 9057-114 | O7: =[1]請求書管理!$O7 -> ◎ | P7: =[1]請求書管理!$P7 -> 0 | Q7: =[1]請求書管理!$Q7 -> INV-260316-104 | R7: =[1]請求書管理!$R7 -> DEL-260316-104 | S7: =[1]請求書管理!$S7 -> REC-260324-104
A8: =[1]請求書管理!$A8 -> 5 | B8: =[1]請求書管理!$B8 -> 株式会社アーキサイト | C8: =[1]請求書管理!$C8 -> 110-0006 | D8: =[1]請求書管理!$D8 -> 東京都台東区秋葉原5番9号 | E8: =[1]請求書管理!$E8 -> 明治安田生命秋葉原ビル | F8: =[1]請求書管理!$F8 -> 03-6859-0281 | G8: =[1]請求書管理!$G8 -> 03-6859-0282 | H8: =[1]請求書管理!$H8 -> https://archisite.co.jp | I8: =[1]請求書管理!$I8 -> 大谷 謙 | J8: =[1]請求書管理!$J8 -> e-mail：koya@archisite.co.jp | K8: =[1]請求書管理!$K8 -> T3010001075632 | L8: =[1]請求書管理!$L8 -> みずほ 銀行本郷 支店 (普) 口座 2681066 | M8: =[1]請求書管理!$M8 -> カ）アーキサイト | N8: =[1]請求書管理!$N8 -> 2483-115 | O8: =[1]請求書管理!$O8 -> × | P8: =[1]請求書管理!$P8 -> 0 | Q8: =[1]請求書管理!$Q8 -> INV-260316-105 | R8: =[1]請求書管理!$R8 -> DEL-260316-105 | S8: =[1]請求書管理!$S8 -> REC-260324-105
A9: =[1]請求書管理!$A9 -> 6 | B9: =[1]請求書管理!$B9 -> TD SYNNEX株式会社 | C9: =[1]請求書管理!$C9 -> 108-0023 | D9: =[1]請求書管理!$D9 -> 東京都港区芝浦3丁目1番1号 | E9: =[1]請求書管理!$E9 -> msb Tamachi 田町ステーションタワーN 21階 | F9: =[1]請求書管理!$F9 -> 03-4595-4550 | G9: =[1]請求書管理!$G9 -> 03-5931-0618 | H9: =[1]請求書管理!$H9 -> https://jp.tdsynnex.com | I9: =[1]請求書管理!$I9 -> 担当：村林 | J9: =[1]請求書管理!$J9 -> t-murabayashi@synnex.co.jp | K9: =[1]請求書管理!$K9 -> T6010601037905 | L9: =[1]請求書管理!$L9 -> 三菱UFJ銀行 田町支店 普通 4576541 | M9: =[1]請求書管理!$M9 -> ティーディーシネックス（カ | N9: =[1]請求書管理!$N9 -> 6712-116 | O9: =[1]請求書管理!$O9 -> ◎ | P9: =[1]請求書管理!$P9 -> https://jp.tdsynnex.com/vendor/vendors#line_sa | Q9: =[1]請求書管理!$Q9 -> INV-260316-106 | R9: =[1]請求書管理!$R9 -> DEL-260316-106 | S9: =[1]請求書管理!$S9 -> REC-260324-106
A10: =[1]請求書管理!$A10 -> 7 | B10: =[1]請求書管理!$B10 -> SB C&S株式会社 | C10: =[1]請求書管理!$C10 -> 105-7529 | D10: =[1]請求書管理!$D10 -> 東京都港区海岸1丁目7番1号 | E10: =[1]請求書管理!$E10 -> 東京ポートシティ竹芝オフィスタワー | F10: =[1]請求書管理!$F10 -> 03-6858-6470 | G10: =[1]請求書管理!$G10 -> 0 | H10: =[1]請求書管理!$H10 -> https://cas.softbank.jp | I10: =[1]請求書管理!$I10 -> 0 | J10: =[1]請求書管理!$J10 -> 0 | K10: =[1]請求書管理!$K10 -> T9010403011485 | L10: =[1]請求書管理!$L10 -> 三菱UFJ銀行 新橋支店 普通 9514626 | M10: =[1]請求書管理!$M10 -> エスビー シーアンドエス（カ | N10: =[1]請求書管理!$N10 -> 4309-117 | O10: =[1]請求書管理!$O10 -> ◎ | P10: =[1]請求書管理!$P10 -> https://www.it-ex.com/makers/ | Q10: =[1]請求書管理!$Q10 -> INV-260316-107 | R10: =[1]請求書管理!$R10 -> DEL-260316-107 | S10: =[1]請求書管理!$S10 -> REC-260324-107
A11: =[1]請求書管理!$A11 -> 8 | B11: =[1]請求書管理!$B11 -> Hamee株式会社 | C11: =[1]請求書管理!$C11 -> 250-0011 | D11: =[1]請求書管理!$D11 -> 神奈川県小田原市栄町2丁目12番10号 | E11: =[1]請求書管理!$E11 -> Square O2 | F11: =[1]請求書管理!$F11 -> 0465-22-8064 | G11: =[1]請求書管理!$G11 -> 0465-22-8065 | H11: =[1]請求書管理!$H11 -> https://hamee.co.jp | I11: =[1]請求書管理!$I11 -> 0 | J11: =[1]請求書管理!$J11 -> oroshi@hamee.co.jp | K11: =[1]請求書管理!$K11 -> T9021001033474 | L11: =[1]請求書管理!$L11 -> みずほ銀行 小田原支店 普通1429575 | M11: =[1]請求書管理!$M11 -> ハミィ（カ | N11: =[1]請求書管理!$N11 -> 8935-118 | O11: =[1]請求書管理!$O11 -> × | P11: =[1]請求書管理!$P11 -> 0 | Q11: =[1]請求書管理!$Q11 -> INV-260316-108 | R11: =[1]請求書管理!$R11 -> DEL-260316-108 | S11: =[1]請求書管理!$S11 -> REC-260324-108
A12: =[1]請求書管理!$A12 -> 9 | B12: =[1]請求書管理!$B12 -> サンディスク合同会社 | C12: =[1]請求書管理!$C12 -> 108-0075 | D12: =[1]請求書管理!$D12 -> 東京都港区港南1丁目6番31号 | E12: =[1]請求書管理!$E12 -> 品川東急ビル3階 | F12: =[1]請求書管理!$F12 -> 0120-893-009 | G12: =[1]請求書管理!$G12 -> 0 | H12: =[1]請求書管理!$H12 -> https://www.sandisk.com | I12: =[1]請求書管理!$I12 -> 0 | J12: =[1]請求書管理!$J12 -> retail_support@sandisk.com | K12: =[1]請求書管理!$K12 -> T2010401090562 | L12: =[1]請求書管理!$L12 -> みずほ銀行 品川支店 普通7759780 | M12: =[1]請求書管理!$M12 -> サンディスク（ド | N12: =[1]請求書管理!$N12 -> 3176-119 | O12: =[1]請求書管理!$O12 -> ◎ | P12: =[1]請求書管理!$P12 -> 0 | Q12: =[1]請求書管理!$Q12 -> INV-260316-109 | R12: =[1]請求書管理!$R12 -> DEL-260316-109 | S12: =[1]請求書管理!$S12 -> REC-260324-109
A13: =[1]請求書管理!$A13 -> 10 | B13: =[1]請求書管理!$B13 -> シー・エフ・デー販売株式会社 | C13: =[1]請求書管理!$C13 -> 460-8315 | D13: =[1]請求書管理!$D13 -> 愛知県名古屋市中区大須3丁目30番20号 | E13: =[1]請求書管理!$E13 -> 赤門通ビル | F13: =[1]請求書管理!$F13 -> 052-249-6606 | G13: =[1]請求書管理!$G13 -> 050-5830-8824 | H13: =[1]請求書管理!$H13 -> https://www.cfd.co.jp | I13: =[1]請求書管理!$I13 -> 0 | J13: =[1]請求書管理!$J13 -> corporate@cfd.co.jp | K13: =[1]請求書管理!$K13 -> T1180001051148 | L13: =[1]請求書管理!$L13 -> 三菱ＵＦＪ銀行 名古屋営業部 普通預金 1488133 | M13: =[1]請求書管理!$M13 -> シー・エフ・デーハンバイ（カ | N13: =[1]請求書管理!$N13 -> 7542-120 | O13: =[1]請求書管理!$O13 -> ◎ | P13: =[1]請求書管理!$P13 -> https://www.cfd.co.jp/biz/brand/sandisk.html#maker-category | Q13: =[1]請求書管理!$Q13 -> INV-260316-110 | R13: =[1]請求書管理!$R13 -> DEL-260316-110 | S13: =[1]請求書管理!$S13 -> REC-260324-110
A14: =[1]請求書管理!$A14 -> 11 | B14: =[1]請求書管理!$B14 -> 加賀電子株式会社 | C14: =[1]請求書管理!$C14 -> 101-8629 | D14: =[1]請求書管理!$D14 -> 東京都千代田区神田松永町20番地 | E14: =[1]請求書管理!$E14 -> 0 | F14: =[1]請求書管理!$F14 -> 03-5657-0111 | G14: =[1]請求書管理!$G14 -> 03-3254-7131 | H14: =[1]請求書管理!$H14 -> https://www.taxan.co.jp/jp | I14: =[1]請求書管理!$I14 -> 0 | J14: =[1]請求書管理!$J14 -> sales2@taxan.co.jp | K14: =[1]請求書管理!$K14 -> T4010001001752 | L14: =[1]請求書管理!$L14 -> みずほ銀行 神田支店 普通7054169 | M14: =[1]請求書管理!$M14 -> カガデンシ（カ | N14: =[1]請求書管理!$N14 -> 2698-121 | O14: =[1]請求書管理!$O14 -> × | P14: =[1]請求書管理!$P14 -> 0 | Q14: =[1]請求書管理!$Q14 -> INV-260316-111 | R14: =[1]請求書管理!$R14 -> DEL-260316-111 | S14: =[1]請求書管理!$S14 -> REC-260324-111
A15: =[1]請求書管理!$A15 -> 12 | B15: =[1]請求書管理!$B15 -> 丸文株式会社 | C15: =[1]請求書管理!$C15 -> 103-8577 | D15: =[1]請求書管理!$D15 -> 東京都中央区日本橋大伝馬町8番1号 | E15: =[1]請求書管理!$E15 -> 0 | F15: =[1]請求書管理!$F15 -> 03-3639-9801 | G15: =[1]請求書管理!$G15 -> 03-3669-2304 | H15: =[1]請求書管理!$H15 -> https://www.marubun.co.jp | I15: =[1]請求書管理!$I15 -> 0 | J15: =[1]請求書管理!$J15 -> info@marubun.co.jp | K15: =[1]請求書管理!$K15 -> T8010001057337 | L15: =[1]請求書管理!$L15 -> 三菱UFJ銀行 大伝馬町支店 普通9914787 | M15: =[1]請求書管理!$M15 -> マルブン（カ | N15: =[1]請求書管理!$N15 -> 6081-122 | O15: =[1]請求書管理!$O15 -> ◎ | P15: =[1]請求書管理!$P15 -> https://www.marubun.co.jp/maker/ | Q15: =[1]請求書管理!$Q15 -> INV-260316-112 | R15: =[1]請求書管理!$R15 -> DEL-260316-112 | S15: =[1]請求書管理!$S15 -> REC-260324-112
... A33: =[1]請求書管理!$A33 -> 109 | B33: =[1]請求書管理!$B33 -> 0 | C33: =[1]請求書管理!$C33 -> 0 | D33: =[1]請求書管理!$D33 -> 0 | E33: =[1]請求書管理!$E33 -> 0 | F33: =[1]請求書管理!$F33 -> 0 | G33: =[1]請求書管理!$G33 -> 0 | H33: =[1]請求書管理!$H33 -> 0 | I33: =[1]請求書管理!$I33 -> 0 | J33: =[1]請求書管理!$J33 -> 0 | K33: =[1]請求書管理!$K33 -> 0 | L33: =[1]請求書管理!$L33 -> 0 | M33: =[1]請求書管理!$M33 -> 0 | N33: =[1]請求書管理!$N33 -> 0 | O33: =[1]請求書管理!$O33 -> 0 | P33: =[1]請求書管理!$P33 -> 0 | Q33: =[1]請求書管理!$Q33 -> 0 | R33: =[1]請求書管理!$R33 -> 0 | S33: =[1]請求書管理!$S33 -> 0

Sheet 目次
B1: 業者名 | C1: 備考 | D1: 備考
A2: 1 | B2: ウエスタンデジタル株式会社
A3: 1_ | B3: ウエスタンデジタル株式会社 | C3: 最新版
A4: 1-2 | B4: ウエスタンデジタル株式会社
A5: 1-3 | B5: サンディスク合同会社
A6: 1-4 | B6: ウエスタンデジタル株式会社 | C6: 数式入り 2026.02.23
A7: 1-5 | B7: ウエスタンデジタル株式会社 | C7: 最新版 | D7: 数式最適化済2026.5.22
A8: 1-6 | B8: サンディスク合同会社 | C8: 最新版 | D8: 数式最適化済2026.5.22
A9: 1-7 | B9: サンディスク合同会社 | C9: 図形バージョン 最新 | D9: 数式最適化済2026.5.22
A10: 1-8 | B10: ウエスタンデジタル株式会社 | C10: 図形バージョン 最新 | D10: 数式最適化済2026.5.22
A11: 2 | B11: キヤノンマーケティングジャパン株式会社
A12: 2-1 | B12: キヤノンマーケティングジャパン株式会社
A13: 2-2 | B13: キヤノンマーケティングジャパン株式会社 | C13: 最新版
A14: 2-3 | B14: キヤノンマーケティングジャパン株式会社 | C14: ジャンコードあり
A15: 2-4 | B15: キヤノンマーケティングジャパン株式会社 | C15: 2026.2.10作成
A16: 2-5 | B16: キヤノンマーケティングジャパン株式会社 | C16: 2026.2.23 作成
A17: 2-6 | B17: キヤノンマーケティングジャパン株式会社 | C17: 2026.2.23 手直し
A18: 2-7 | B18: キヤノンマーケティングジャパン株式会社 | C18: 最新版
A19: 3 | B19: SB C＆S 株式会社
A20: 3-1 | B20: SB C＆S 株式会社 | C20: 修正版
A21: 4-1 | B21: 浜田電機株式会社
A22: 4-2 | B22: 浜田電機株式会社
A23: 4-3 | B23: 浜田電機株式会社
A24: 4-4 | B24: 浜田電機株式会社
A25: 4-5 | B25: 浜田電機株式会社
A26: 4-6 | B26: 浜田電機株式会社
A27: 4-7 | B27: 浜田電機株式会社
A28: 4-8 | B28: 浜田電機株式会社
A29: 4-9 | B29: 浜田電機株式会社 | C29: インボイスなし
A30: 5 | B30: 株式会社ビックカメラ
A31: 6 | B31: 株式会社ヤマダ電機（ツクモ）
A32: 7-1 | B32: ダイワボウ情報システム株式会社
A33: 7-2 | B33: ダイワボウ情報システム株式会社
A34: 7-3 | B34: ダイワボウ情報システム株式会社
A35: 8-1 | B35: 東映無線株式会社 アスビック
A36: 8-2 | B36: 東映無線株式会社 アスビック
A37: 8-3 | B37: 東映無線株式会社 アスビック
A38: 8-4 | B38: 東映無線株式会社 アスビック
A39: 8-5 | B39: 東映無線株式会社 アスビック | C39: 最新版
A40: 9 | B40: 株式会社アーキサイト
...

Sheet 会計フリー
A1: 請求書
A2: 東映無線株式会社 御中
E3: 請求日 | F3: 45762
A4: 〒11010021 | E4: 請求書番号 | F4: 3003877451
A5: 東京都千代田区外神田1丁目10番11号 | E5: 登録番号 | F5: T2010401090562
A6: 東京ラジオデパート内
A7: TEL：03-3527-1006
A8: 登録番号T1010001023790 | E8: ウエスタンデジタル合同会社
E9: 〒108-0075
E10: 東京都港区港南1丁目6番31号
E11: 品川東急ビル 3階
E12: TEL：0120-893-009
E13: https://shop.sandisk.com
E14: westerndigital_jp@custhelp.com
A15: 下記の通りご請求申し上げます。
A16: 件名 | B16: SanDisk製品の件
A17: 小計 | B17: 消費税 | C17: 請求金額
A18: =F42 -> 144900 | B18: =F43 -> 14490 | C18: =A18+B18 -> 159390 | I18: №
I19: 1 | J19: 180 | K19: 型番： | L19: SDSQXA2-064G-GN6MA | M19: コード： | N19: 619659169770 | O19: SanDisk | Q19: 89 | R19: 4 | S19: 150
A20: 入金期日 | B20: 振込先 | I20: 2 | J20: 199 | K20: 型番： | L20: SDSQXA1-128G-GN6MN | M20: コード： | N20: 619659180034 | O20: SanDisk | Q20: 114 | R20: 5 | S20: 550
A21: 45765 | B21: みずほ銀行 品川支店 普通7759780 | I21: 3 | J21: 214 | K21: 型番： | L21: SDSQXA1-256G-GN6MN | M21: コード： | N21: 619659180041 | O21: SanDisk | Q21: 167 | R21: 15 | S21: 50
I22: 4 | J22: 89 | K22: 型番： | L22: SDSQUAB-128G-GH3MA | M22: コード： | N22: 619659201579 | O22: SanDisk | Q22: 179 | R22: 16 | S22: 80
A23: 摘要 | D23: 数量 | E23: 単価 | F23: 明細金額 | I23: 5 | J23: 114 | K23: 型番： | L23: SDSQUAC-256G-GH3MA | M23: コード： | N23: 619659201555 | O23: SanDisk | Q23: 197 | R23: 17 | S23: 150
A24: =O19&" "&M19&N19&" "&K19&L19 -> SanDisk コード：619659169770 型番：SDSQXA2-064G-GN6MA | D24: 300 | E24: 0 | F24: =E24*D24 -> 0 | I24: 6 | J24: 287 | K24: 型番： | L24: SDSQQNR-032G-GH3IA | M24: コード： | N24: 619659197704 | O24: SanDisk | Q24: 212 | S24: 70
A25: =O20&" "&M20&N20&" "&K20&L20 -> SanDisk コード：619659180034 型番：SDSQXA1-128G-GN6MN | D25: 350 | E25: 0 | F25: =E25*D25 -> 0 | I25: 7 | J25: 292 | K25: 型番： | L25: SDSQQNR-064G-GH3IA | M25: コード： | N25: 619659197711 | O25: SanDisk | Q25: 287 | R25: 6 | S25: 35
A26: =O21&" "&M21&N21&" "&K21&L21 -> SanDisk コード：619659180041 型番：SDSQXA1-256G-GN6MN | D26: 150 | E26: 0 | F26: =E26*D26 -> 0 | I26: 8 | J26: 297 | K26: 型番： | L26: SDSQQNR-128G-GH3IA | M26: コード： | N26: 619659198923 | O26: SanDisk | Q26: 292 | R26: 7 | S26: 40
A27: =O22&" "&M22&N22&" "&K22&L22 -> SanDisk コード：619659201579 型番：SDSQUAB-128G-GH3MA | D27: 150 | E27: 70 | F27: =E27*D27 -> 10500 | I27: 9 | J27: 195 | K27: 型番： | L27: SDSQXAH-064G-GN6MN | M27: コード： | N27: 619659193416 | O27: SanDisk | Q27: 297 | R27: 8 | S27: 70
A28: =O23&" "&M23&N23&" "&K23&L23 -> SanDisk コード：619659201555 型番：SDSQUAC-256G-GH3MA | D28: 20 | E28: 0 | F28: =E28*D28 -> 0 | I28: 10 | J28: 198 | K28: 型番： | L28: SDSQXAA-128G-GN6MN | M28: コード： | N28: 619659188467 | O28: SanDisk | Q28: 302 | S28: 25
A29: =O24&" "&M24&N24&" "&K24&L24 -> SanDisk コード：619659197704 型番：SDSQQNR-032G-GH3IA | D29: 35 | E29: 0 | F29: =E29*D29 -> 0 | I29: 11 | J29: 213 | K29: 型番： | L29: SDSQXAV-256G-GN6MN | M29: コード： | N29: 619659188511 | O29: SanDisk | Q29: 365 | R29: 12 | S29: 50
A30: =O25&" "&M25&N25&" "&K25&L25 -> SanDisk コード：619659197711 型番：SDSQQNR-064G-GH3IA | D30: 40 | E30: 0 | F30: =E30*D30 -> 0 | I30: 12 | J30: 365 | K30: 型番： | L30: SDSDXV2-064G-GHJIN | M30: コード： | N30: 619659197834 | O30: SanDisk | Q30: 373 | R30: 13 | S30: 650
A31: =O26&" "&M26&N26&" "&K26&L26 -> SanDisk コード：619659198923 型番：SDSQQNR-128G-GH3IA | D31: 70 | E31: 0 | F31: =E31*D31 -> 0 | I31: 13 | J31: 373 | K31: 型番： | L31: SDSDXVA-128G-GHJIN | M31: コード： | N31: 619659197841 | O31: SanDisk | Q31: 380 | R31: 14 | S31: 250
A32: =O27&" "&M27&N27&" "&K27&L27 -> SanDisk コード：619659193416 型番：SDSQXAH-064G-GN6MN | D32: 90 | E32: 100 | F32: =E32*D32 -> 9000 | I32: 14 | J32: 380 | K32: 型番： | L32: SDSDXVV-256G-GHJIN | M32: コード： | N32: 619659197858 | O32: SanDisk | Q32: 407 | S32: 350
A33: =O28&" "&M28&N28&" "&K28&L28 -> SanDisk コード：619659188467 型番：SDSQXAA-128G-GN6MN | D33: 400 | E33: 125 | F33: =E33*D33 -> 50000 | I33: 15 | J33: 167 | K33: 型番： | L33: SDSQXAT-032G-GH3MA | M33: コード： | N33: 619659197940 | O33: SanDisk | Q33: 419 | S33: 100
A34: =O29&" "&M29&N29&" "&K29&L29 -> SanDisk コード：619659188511 型番：SDSQXAV-256G-GN6MN | D34: 390 | E34: 40 | F34: =E34*D34 -> 15600 | I34: 16 | J34: 179 | K34: 型番： | L34: SDSQXAH-064G-GH3MA | M34: コード： | N34: 619659197933 | O34: SanDisk | Q34: 434 | S34: 20
A35: =O30&" "&M30&N30&" "&K30&L30 -> SanDisk コード：619659197834 型番：SDSDXV2-064G-GHJIN | D35: 50 | E35: 0 | F35: =E35*D35 -> 0 | I35: 17 | J35: 197 | K35: 型番： | L35: SDSQXAA-128G-GH3MA | M35: コード： | N35: 619659197926 | O35: SanDisk | Q35: 437 | S35: 15
A36: =O31&" "&M31&N31&" "&K31&L31 -> SanDisk コード：619659197841 型番：SDSDXVA-128G-GHJIN | D36: 650 | E36: 50 | F36: =E36*D36 -> 32500 | I36: 18 | K36: 型番： | L36: #N/A | M36: コード： | N36: #N/A | O36: SanDisk | Q36: 180 | R36: 1 | S36: 300
A37: =O32&" "&M32&N32&" "&K32&L32 -> SanDisk コード：619659197858 型番：SDSDXVV-256G-GHJIN | D37: 250 | E37: 0 | F37: =E37*D37 -> 0 | I37: 19 | K37: 型番： | L37: #N/A | M37: コード： | N37: #N/A | O37: SanDisk | Q37: 199 | R37: 2 | S37: 350
A38: =O33&" "&M33&N33&" "&K33&L33 -> SanDisk コード：619659197940 型番：SDSQXAT-032G-GH3MA | D38: 50 | E38: 0 | F38: =E38*D38 -> 0 | I38: 20 | K38: 型番： | L38: #N/A | M38: コード： | N38: #N/A | O38: SanDisk | Q38: 214 | R38: 3 | S38: 150
A39: =O34&" "&M34&N34&" "&K34&L34 -> SanDisk コード：619659197933 型番：SDSQXAH-064G-GH3MA | D39: 80 | E39: 60 | F39: =E39*D39 -> 4800 | I39: 21 | K39: 型番： | L39: #N/A | M39: コード： | N39: #N/A | O39: SanDisk | Q39: 168 | S39: 80
A40: =O35&" "&M35&N35&" "&K35&L35 -> SanDisk コード：619659197926 型番：SDSQXAA-128G-GH3MA | D40: 150 | E40: 150 | F40: =E40*D40 -> 22500 | I40: 22 | K40: 型番： | L40: #N/A | M40: コード： | N40: #N/A | O40: SanDisk | Q40: 195 | R40: 9 | S40: 90
...

Sheet 会計フリー　最新 
A1: 請求書
A2: =VLOOKUP(管理!$C$2,管理!$A$4:$V$100,2,0)&" 御中" -> 柏尾奏利（KASIOshop） 御中
E3: 請求日 | G3: =管理!F1 -> 46097
A4: ="〒"&VLOOKUP(管理!$C$2,管理!$A$4:$V$100,3,0) -> 〒174-0072 | E4: 請求書番号 | G4: =VLOOKUP(管理!$C$1,管理!$A$4:$V$100,15,0) -> ◎
A5: =VLOOKUP(管理!$C$2,管理!$A$4:$V$100,4,0) -> 東京都板橋区南常盤台1丁目11番6号 | E5: 登録番号 | G5: =VLOOKUP(管理!$C$1,管理!$A$4:$V$100,11,0) -> T2010401090562
A6: =VLOOKUP(管理!$C$2,管理!$A$4:$V$100,5,0) -> ウエアーハウス303号室
A7: ="担当者："&VLOOKUP(管理!$C$2,管理!A4:S50,9,0)&" 様" -> 担当者：柏尾奏利 様
E8: =VLOOKUP(管理!$C$1,管理!$A$4:$V$100,2,0) -> サンディスク合同会社
E9: ="〒"&VLOOKUP(管理!$C$1,管理!$A$4:$V$100,3,0) -> 〒108-0075
E10: =VLOOKUP(管理!$C$1,管理!$A$4:$V$100,4,0) -> 東京都港区港南1丁目6番31号
E11: =VLOOKUP(管理!$C$1,管理!$A$4:$V$100,5,0) -> 品川東急ビル3階
E12: TEL | F12: =VLOOKUP(管理!$C$1,管理!$A$4:$V$100,6,0) -> 0120-893-009
E13: MAIL | F13: =VLOOKUP(管理!$C$1,管理!$A$4:$V$100,8,0) -> https://www.sandisk.com
E14: WEB | F14: =VLOOKUP(管理!$C$1,管理!$A$4:$V$100,10,0) -> retail_support@sandisk.com
A15: 下記の通りご請求申し上げます。
A16: 件名 | B16: SanDisk製品の件
A17: 小計 | B17: 消費税 | C17: 請求金額
A18: =G42 -> 2050055 | B18: =G43 -> 205005.5 | C18: =A18+B18 -> 2255060.5 | J18: №
J19: 1 | K19: 180 | L19: 型番： | M19: SDSQXA2-064G-GN6MA | N19: コード： | O19: 619659169770 | P19: SanDisk | R19: 89 | S19: 4 | T19: 150
A20: 入金期日 | B20: 振込先 | J20: 2 | K20: 199 | L20: 型番： | M20: SDSQXA1-128G-GN6MN | N20: コード： | O20: 619659180034 | P20: SanDisk | R20: 114 | S20: 5 | T20: 550
A21: =管理!O1 -> 46105 | B21: =VLOOKUP(管理!$C$1,管理!$A$4:$V$100,12,0) -> みずほ銀行 品川支店 普通7759780 | J21: 3 | K21: 214 | L21: 型番： | M21: SDSQXA1-256G-GN6MN | N21: コード： | O21: 619659180041 | P21: SanDisk | R21: 167 | S21: 15 | T21: 50
J22: 4 | K22: 89 | L22: 型番： | M22: SDSQUAB-128G-GH3MA | N22: コード： | O22: 619659201579 | P22: SanDisk | R22: 179 | S22: 16 | T22: 80
A23: 摘要 | D23: 数量 | E23: 単価 | G23: 明細金額 | J23: 5 | K23: 114 | L23: 型番： | M23: SDSQUAC-256G-GH3MA | N23: コード： | O23: 619659201555 | P23: SanDisk | R23: 197 | S23: 17 | T23: 150
A24: SanDisk 商品コード：619659201593 商品モデル番号：SDSQUA4-032G-GH3MA | D24: 0 | E24: 1463 | G24: =E24*D24 -> 0 | J24: 6 | K24: 287 | L24: 型番： | M24: SDSQQNR-032G-GH3IA | N24: コード： | O24: 619659197704 | P24: SanDisk | R24: 212 | T24: 70
A25: SanDisk 商品コード：619659201586 商品モデル番号：SDSQUAB-064G-GH3MA | D25: 0 | E25: 1715 | G25: =E25*D25 -> 0 | J25: 7 | K25: 292 | L25: 型番： | M25: SDSQQNR-064G-GH3IA | N25: コード： | O25: 619659197711 | P25: SanDisk | R25: 287 | S25: 6 | T25: 35
A26: SanDisk 商品コード：619659201579 商品モデル番号：SDSQUAB-128G-GH3MA | D26: 70 | E26: 2555 | G26: =E26*D26 -> 178850 | J26: 8 | K26: 297 | L26: 型番： | M26: SDSQQNR-128G-GH3IA | N26: コード： | O26: 619659198923 | P26: SanDisk | R26: 292 | S26: 7 | T26: 40
A27: SanDisk 商品コード：619659200480 商品モデル番号：SDSQUAB-128G-GN6MN | D27: 55 | E27: 2555 | G27: =E27*D27 -> 140525 | J27: 9 | K27: 195 | L27: 型番： | M27: SDSQXAH-064G-GN6MN | N27: コード： | O27: 619659193416 | P27: SanDisk | R27: 297 | S27: 8 | T27: 70
A28: SanDisk 商品コード：619659201555 商品モデル番号：SDSQUAC-256G-GH3MA | D28: 0 | E28: 4445 | G28: =E28*D28 -> 0 | J28: 10 | K28: 198 | L28: 型番： | M28: SDSQXAA-128G-GN6MN | N28: コード： | O28: 619659188467 | P28: SanDisk | R28: 302 | T28: 25
A29: SanDisk 商品コード：619659201562 商品モデル番号：SDSQUAC-512G-GH3MA | D29: 0 | E29: 8050 | G29: =E29*D29 -> 0 | J29: 11 | K29: 213 | L29: 型番： | M29: SDSQXAV-256G-GN6MN | N29: コード： | O29: 619659188511 | P29: SanDisk | R29: 365 | S29: 12 | T29: 50
A30: SanDisk 商品コード：619659201609 商品モデル番号：SDSQUAC-1T00-GH3MA | D30: 0 | E30: 15470 | G30: =E30*D30 -> 0 | J30: 12 | K30: 365 | L30: 型番： | M30: SDSDXV2-064G-GHJIN | N30: コード： | O30: 619659197834 | P30: SanDisk | R30: 373 | S30: 13 | T30: 650
A31: SanDisk 商品コード：619659203566 商品モデル番号：SDSQUAC-1T50-GH3MA | D31: 0 | E31: 17220 | G31: =E31*D31 -> 0 | J31: 13 | K31: 373 | L31: 型番： | M31: SDSDXVA-128G-GHJIN | N31: コード： | O31: 619659197841 | P31: SanDisk | R31: 380 | S31: 14 | T31: 250
A32: SanDisk 商品コード：619659197940 商品モデル番号：SDSQXAT-032G-GH3MA | D32: 0 | E32: 1785 | G32: =E32*D32 -> 0 | J32: 14 | K32: 380 | L32: 型番： | M32: SDSDXVV-256G-GHJIN | N32: コード： | O32: 619659197858 | P32: SanDisk | R32: 407 | T32: 350
A33: SanDisk 商品コード：619659197933 商品モデル番号：SDSQXAH-064G-GH3MA | D33: 60 | E33: 2093 | G33: =E33*D33 -> 125580 | J33: 15 | K33: 167 | L33: 型番： | M33: SDSQXAT-032G-GH3MA | N33: コード： | O33: 619659197940 | P33: SanDisk | R33: 419 | T33: 100
A34: SanDisk 商品コード：619659193416 商品モデル番号：SDSQXAH-064G-GN6MN | D34: 100 | E34: 2093 | G34: =E34*D34 -> 209300 | J34: 16 | K34: 179 | L34: 型番： | M34: SDSQXAH-064G-GH3MA | N34: コード： | O34: 619659197933 | P34: SanDisk | R34: 434 | T34: 20
A35: SanDisk 商品コード：619659197926 商品モデル番号：SDSQXAA-128G-GH3MA | D35: 150 | E35: 2926 | G35: =E35*D35 -> 438900 | J35: 17 | K35: 197 | L35: 型番： | M35: SDSQXAA-128G-GH3MA | N35: コード： | O35: 619659197926 | P35: SanDisk | R35: 437 | T35: 15
A36: SanDisk 商品コード：619659188467 商品モデル番号：SDSQXAA-128G-GN6MN | D36: 125 | E36: 2926 | G36: =E36*D36 -> 365750 | J36: 18 | L36: 型番： | M36: #N/A | N36: コード： | O36: #N/A | P36: SanDisk | R36: 180 | S36: 1 | T36: 300
A37: SanDisk 商品コード：619659197964 商品モデル番号：SDSQXAV-256G-GH3MA | D37: 35 | E37: 5530 | G37: =E37*D37 -> 193550 | J37: 19 | L37: 型番： | M37: #N/A | N37: コード： | O37: #N/A | P37: SanDisk | R37: 199 | S37: 2 | T37: 350
A38: SanDisk 商品コード：619659188511 商品モデル番号：SDSQXAV-256G-GN6MN | D38: 40 | E38: 5530 | G38: =E38*D38 -> 221200 | J38: 20 | L38: 型番： | M38: #N/A | N38: コード： | O38: #N/A | P38: SanDisk | R38: 214 | S38: 3 | T38: 150
A39: SanDisk 商品コード：619659197971 商品モデル番号：SDSQXAV-512G-GH3MA | D39: 20 | E39: 8820 | G39: =E39*D39 -> 176400 | J39: 21 | L39: 型番： | M39: #N/A | N39: コード： | O39: #N/A | P39: SanDisk | R39: 168 | T39: 80
A40: SanDisk 商品コード：619659197957 商品モデル番号：SDSQXAV-1T00-GH3MA | D40: 0 | E40: 16660 | G40: =E40*D40 -> 0 | J40: 22 | L40: 型番： | M40: #N/A | N40: コード： | O40: #N/A | P40: SanDisk | R40: 195 | S40: 9 | T40: 90
...

Sheet エレコムダイレクトショップ本店
B2: 〒174-0072
B3: 東京都板橋区南常盤台1丁目11番6号
B4: ウエアーハウス303号室 | H4: 46062
G5: 登録番号: T5120001094974
B6: 柏尾奏利（KASIOshop） 様 | G6: 〒541-8765
D7: 請求書在中 | G7: 大阪市中央区伏見町4丁目1番1号
G8: 明治安田生命大阪御堂筋ビル9F
G9: エレコムダイレクトショップ本店
B11: 請求書 | M11: № | P11: 型番 | R11: JANコード
B12: 〒174-0072 | M12: 1 | N12: 63 | O12: 型番： | P12: SDSQUAB-064G-GN6MN | Q12: JANコード： | R12: 4549550356145
B13: 東京都板橋区南常盤台1丁目11番6号 | G13: 請求書No.： | H13: ORDER-198103 | M13: 2 | N13: 90 | O13: 型番： | P13: SDSQUAB-128G-GN6MN | Q13: JANコード： | R13: 619659200480
B14: ウエアーハウス303号室 | G14: お客様番号： | H14: 187271 | M14: 3 | N14: 115 | O14: 型番： | P14: SDSQUAC-256G-GN6MN | Q14: JANコード： | R14: 619659200497
B15: 柏尾奏利（KASIOshop） 様 | M15: 4 | N15: 138 | O15: 型番： | P15: SDSQUAC-512G-GN6MN | Q15: JANコード： | R15: 619659200503
B16: 取引日：2026年2月9日 | M16: 5 | N16: 168 | O16: 型番： | P16: SDSQXAF-032G-GN6MN | Q16: JANコード： | R16: 619659177416
B17: 支払方法：下記の口座にお振込願います。 | M17: 6 | N17: 180 | O17: 型番： | P17: SDSQXA2-064G-GN6MA | Q17: JANコード： | R17: 619659169770
B18: 支払期日：2026年2月20日 | M18: 7 | N18: 199 | O18: 型番： | P18: SDSQXA1-128G-GN6MN | Q18: JANコード： | R18: 619659180034
B19: お振込口座： | D19: 三井住友銀行 | M19: 8 | N19: 214 | O19: 型番： | P19: SDSQXA1-256G-GN6MN | Q19: JANコード： | R19: 619659180041
D20: 備後町支店 (支店コード：103) | M20: 9 | N20: 195 | O20: 型番： | P20: SDSQXAH-064G-GN6MN | Q20: JANコード： | R20: 619659193416
D21: 普通 1583633 | M21: 10 | N21: 198 | O21: 型番： | P21: SDSQXAA-128G-GN6MN | Q21: JANコード： | R21: 619659188467
D22: エレコム（カ | M22: 11 | N22: 213 | O22: 型番： | P22: SDSQXAV-256G-GN6MN | Q22: JANコード： | R22: 619659188511
M23: 12 | N23: 230 | O23: 型番： | P23: SDSQXAV-512G-GN6MN | Q23: JANコード： | R23: 619659189655
B24: № | C24: 製品名 | E24: 単価 | G24: 数量 | H24: 商品金額 | M24: 13 | N24: 330 | O24: 型番： | P24: SDSDUNB-064G-GH3NN | Q24: JANコード： | R24: 619659200671
M25: 14 | N25: 340 | O25: 型番： | P25: SDSDUNB-128G-GH3NN | Q25: JANコード： | R25: 619659200107
B26: 1 | C26: iPhone 16e ハイブリッドガラスケース 極限 メタルステッカー付 PM-A25SHVCGKCR 商品コード：4549550356145 | E26: 100 | G26: 50 | H26: =E26*G26 -> 5000 | M26: 15 | N26: 350 | O26: 型番： | P26: SDSDUNC-256G-GH3NN | Q26: JANコード： | R26: 619659200701
M27: 16 | N27: 390 | O27: 型番： | P27: SDSDXXO-032G-GN4IN | Q27: JANコード： | R27: 619659188689
B28: 2 | C28: iPhone 16e ソフトケース サイドメッキ メタルステッカー付 PM-A25SUCTMBU 商品コード：4549550357326 | E28: 100 | G28: 50 | H28: =E28*G28 -> 5000
C42: =O28&P28&" "&Q28&R28
B48: ＜納品先住所＞ | F48: 送料 | H48: 0
B49: =B12 -> 〒174-0072
B50: =B13 -> 東京都板橋区南常盤台1丁目11番6号 | F50: 税抜合計 | H50: =SUM(H24:I27) -> 5000
B51: =B14 -> ウエアーハウス303号室 | F51: 消費税10％対象 | H51: =H50*10% -> 500
F52: 税込合計 | H52: =H50+H51 -> 5500
B53: =B15 -> 柏尾奏利（KASIOshop） 様
C54: TEL：090-7446-7403 | F54: 支払合計 | H54: =H52+H53 -> 5500

Sheet エレコム株式会社
A2: 〒174-0072
A3: 東京都板橋区南常盤台1丁目11番6号
A4: ウエアーハウス303号室 | G4: 46062
F5: 登録番号: T5120001094974
A6: 柏尾奏利（KASIOshop） 様 | F6: 〒541-8765
C7: 請求書在中 | F7: 大阪市中央区伏見町4丁目1番1号
F8: 明治安田生命大阪御堂筋ビル9F
F9: エレコム株式会社
A11: 請求書 | L11: № | O11: 型番 | Q11: JANコード
A12: 〒174-0072 | L12: 1 | M12: 63 | N12: 型番： | O12: SDSQUAB-064G-GN6MN | P12: JANコード： | Q12: 4549550356145
A13: 東京都板橋区南常盤台1丁目11番6号 | F13: 請求書No.： | G13: ORDER-198103 | L13: 2 | M13: 90 | N13: 型番： | O13: SDSQUAB-128G-GN6MN | P13: JANコード： | Q13: 619659200480
A14: ウエアーハウス303号室 | F14: お客様番号： | G14: 187271 | L14: 3 | M14: 115 | N14: 型番： | O14: SDSQUAC-256G-GN6MN | P14: JANコード： | Q14: 619659200497
A15: 柏尾奏利（KASIOshop） 様 | L15: 4 | M15: 138 | N15: 型番： | O15: SDSQUAC-512G-GN6MN | P15: JANコード： | Q15: 619659200503
A16: 取引日：2026年2月9日 | L16: 5 | M16: 168 | N16: 型番： | O16: SDSQXAF-032G-GN6MN | P16: JANコード： | Q16: 619659177416
A17: 支払方法：下記の口座にお振込願います。 | L17: 6 | M17: 180 | N17: 型番： | O17: SDSQXA2-064G-GN6MA | P17: JANコード： | Q17: 619659169770
A18: 支払期日：2026年2月20日 | L18: 7 | M18: 199 | N18: 型番： | O18: SDSQXA1-128G-GN6MN | P18: JANコード： | Q18: 619659180034
A19: お振込口座： | C19: 三井住友銀行 | L19: 8 | M19: 214 | N19: 型番： | O19: SDSQXA1-256G-GN6MN | P19: JANコード： | Q19: 619659180041
C20: 備後町支店 (支店コード：103) | L20: 9 | M20: 195 | N20: 型番： | O20: SDSQXAH-064G-GN6MN | P20: JANコード： | Q20: 619659193416
C21: 普通 1583633 | L21: 10 | M21: 198 | N21: 型番： | O21: SDSQXAA-128G-GN6MN | P21: JANコード： | Q21: 619659188467
C22: エレコム（カ | L22: 11 | M22: 213 | N22: 型番： | O22: SDSQXAV-256G-GN6MN | P22: JANコード： | Q22: 619659188511
L23: 12 | M23: 230 | N23: 型番： | O23: SDSQXAV-512G-GN6MN | P23: JANコード： | Q23: 619659189655
A24: № | B24: 製品名 | D24: 単価 | F24: 数量 | G24: 商品金額 | L24: 13 | M24: 330 | N24: 型番： | O24: SDSDUNB-064G-GH3NN | P24: JANコード： | Q24: 619659200671
L25: 14 | M25: 340 | N25: 型番： | O25: SDSDUNB-128G-GH3NN | P25: JANコード： | Q25: 619659200107
A26: 1 | B26: iPhone 16e ハイブリッドガラスケース 極限 メタルステッカー付 PM-A25SHVCGKCR 商品コード：4549550356145 | D26: 100 | F26: 50 | G26: =D26*F26 -> 5000 | L26: 15 | M26: 350 | N26: 型番： | O26: SDSDUNC-256G-GH3NN | P26: JANコード： | Q26: 619659200701
L27: 16 | M27: 390 | N27: 型番： | O27: SDSDXXO-032G-GN4IN | P27: JANコード： | Q27: 619659188689
A28: 2 | B28: iPhone 16e ソフトケース サイドメッキ メタルステッカー付 PM-A25SUCTMBU 商品コード：4549550357326 | D28: 100 | F28: 50 | G28: =D28*F28 -> 5000
B42: =N28&O28&" "&P28&Q28
A48: ＜納品先住所＞ | E48: 送料 | G48: 0
A49: =A12 -> 〒174-0072
A50: =A13 -> 東京都板橋区南常盤台1丁目11番6号 | E50: 税抜合計 | G50: =SUM(G24:H27) -> 5000
A51: =A14 -> ウエアーハウス303号室 | E51: 消費税10％対象 | G51: =G50*10% -> 500
E52: 税込合計 | G52: =G50+G51 -> 5500
A53: =A15 -> 柏尾奏利（KASIOshop） 様
B54: TEL：090-7446-7403 | E54: 支払合計 | G54: =G52+G53 -> 5500

Sheet エレコム株式会社　最新
A2: ="〒"&VLOOKUP(管理!$C$2,管理!$A$4:$V$100,3,0) -> 〒174-0072
A3: =VLOOKUP(管理!$C$2,管理!$A$4:$V$100,4,0) -> 東京都板橋区南常盤台1丁目11番6号
A4: =VLOOKUP(管理!$C$2,管理!$A$4:$V$100,5,0) -> ウエアーハウス303号室 | H4: =管理!F1 -> 46097
G5: ="登録番号："&VLOOKUP(管理!$C$1,管理!A4:T53,11,0) -> 登録番号：T2010401090562
A6: =VLOOKUP(管理!$C$2,管理!$A$4:$V$100,2,0)&" 御中" -> 柏尾奏利（KASIOshop） 御中 | G6: ="〒"&VLOOKUP(管理!$C$1,管理!A4:T53,3,0) -> 〒108-0075
C7: 請求書在中 | G7: =VLOOKUP(管理!$C$1,管理!A4:T53,4,0) -> 東京都港区港南1丁目6番31号
G8: =VLOOKUP(管理!$C$1,管理!A4:T53,5,0) -> 品川東急ビル3階
G9: =VLOOKUP(管理!$C$1,管理!A4:T53,2,0) -> サンディスク合同会社
A11: 請求書
A12: =A2 -> 〒174-0072
A13: =A3 -> 東京都板橋区南常盤台1丁目11番6号 | G13: 請求書No. | H13: =VLOOKUP(管理!$C$1,管理!A4:T53,15,0) -> ◎
A14: =A4 -> ウエアーハウス303号室 | G14: お客様番号 | H14: =VLOOKUP(管理!$C$1,管理!A4:T53,14,0) -> 3176-119
A15: =A6 -> 柏尾奏利（KASIOshop） 御中
A16: 取引日 | C16: =H4 -> 46097
A17: 支払方法 | C17: 下記の口座にお振込願います。
A18: 支払期日 | C18: =管理!O1 -> 46105
A19: お振込口座 | C19: =VLOOKUP(管理!$C$1,管理!$A$4:$V$100,12,0) -> みずほ銀行 品川支店 普通7759780
C20: =VLOOKUP(管理!$C$1,管理!$A$4:$V$100,13,0) -> サンディスク（ド
A22: № | B22: 製品名 | E22: 単価 | G22: 数量 | H22: 商品金額
A24: 1 | B24: メーカー：SanDisk 商品コード：619659201593 商品モデル番号：SDSQUA4-032G-GH3MA | E24: 1463 | G24: 0 | H24: =E24*G24 -> 0
A25: 2 | B25: メーカー：SanDisk 商品コード：619659201586 商品モデル番号：SDSQUAB-064G-GH3MA | E25: 1715 | G25: 0 | H25: =E25*G25 -> 0
A26: 3 | B26: メーカー：SanDisk 商品コード：619659201579 商品モデル番号：SDSQUAB-128G-GH3MA | E26: 2555 | G26: 70 | H26: =E26*G26 -> 178850
A27: 4 | B27: メーカー：SanDisk 商品コード：619659200480 商品モデル番号：SDSQUAB-128G-GN6MN | E27: 2555 | G27: 55 | H27: =E27*G27 -> 140525
A28: 5 | B28: メーカー：SanDisk 商品コード：619659201555 商品モデル番号：SDSQUAC-256G-GH3MA | E28: 4445 | G28: 0 | H28: =E28*G28 -> 0
A29: 6 | B29: メーカー：SanDisk 商品コード：619659201562 商品モデル番号：SDSQUAC-512G-GH3MA | E29: 8050 | G29: 0 | H29: =E29*G29 -> 0
A30: 7 | B30: メーカー：SanDisk 商品コード：619659201609 商品モデル番号：SDSQUAC-1T00-GH3MA | E30: 15470 | G30: 0 | H30: =E30*G30 -> 0
A31: 8 | B31: メーカー：SanDisk 商品コード：619659203566 商品モデル番号：SDSQUAC-1T50-GH3MA | E31: 17220 | G31: 0 | H31: =E31*G31 -> 0
A32: 9 | B32: メーカー：SanDisk 商品コード：619659197940 商品モデル番号：SDSQXAT-032G-GH3MA | E32: 1785 | G32: 0 | H32: =E32*G32 -> 0
A33: 10 | B33: メーカー：SanDisk 商品コード：619659197933 商品モデル番号：SDSQXAH-064G-GH3MA | E33: 2093 | G33: 60 | H33: =E33*G33 -> 125580
A34: 11 | B34: メーカー：SanDisk 商品コード：619659193416 商品モデル番号：SDSQXAH-064G-GN6MN | E34: 2093 | G34: 100 | H34: =E34*G34 -> 209300
A35: 12 | B35: メーカー：SanDisk 商品コード：619659197926 商品モデル番号：SDSQXAA-128G-GH3MA | E35: 2926 | G35: 150 | H35: =E35*G35 -> 438900
... A44: 21 | B44: メーカー：SanDisk 商品コード：619659198923 商品モデル番号：SDSQQNR-128G-GH3IA | E44: 3080 | G44: 0 | H44: =E44*G44 -> 0
A46: ＜納品先住所＞ | F46: 送料 | H46: 0
A47: =A12 -> 〒174-0072
A48: =A13 -> 東京都板橋区南常盤台1丁目11番6号 | F48: 税抜合計 | H48: =SUM(H24:I27) -> 319375
A49: =A14 -> ウエアーハウス303号室 | F49: 消費税10％対象 | H49: =H48*10% -> 31937.5
F50: 税込合計 | H50: =H48+H49 -> 351312.5
A51: =VLOOKUP(管理!$C$2,管理!$A$4:$V$100,2,0) -> 柏尾奏利（KASIOshop）
B52: ="TEL："&VLOOKUP(管理!$C$2,管理!$A$4:$V$100,6,0) -> TEL：03-3600-3333 | F52: 支払合計 | H52: =H50+H51 -> 351312.5

Sheet 1_見積書
A3: 御見積書
A5: 株式会社レイディスク 御中
F6: NO | G6: 1285
F7: 見積日 | G7: 2025.7.28
A9: 下記の通り、お見積り申し上げます。 | F9: 〒108-0075
A10: 件名 | B10: 特価ご依頼の件 | F10: 東京都港区港南1-6-31 品川東急ビル3F
A11: 納期 | B11: 決済後1～2営業日 | F11: ウエスタンデジタル合同会社
A12: 支払条件 | B12: クレジットカード払い | F12: TEL:03-4334-7100(代) FAX:03-5463-2010(代)
A13: 有効期限 | B13: 御見積後1週間
A15: 合計 | B15: 48,620円（税込）
A17: 摘要 | E17: 数量 | F17: 単位 | G17: 単価（税別） | H17: 金額
A18: SDSQQNR-128G-GH3IA | E18: 20 | F18: 式 | G18: 2210 | H18: 44200
G28: 合計（税別） | H28: 44200
G29: 消費税 | H29: 4420
G30: 合計（税込） | H30: 48620
A32: 備考

Sheet 1_請求書
D2: ウエスタンデジタル合同会社 | M2: 請求書 兼 領収書
D3: 〒108-0075 東京都港区港南1-6-31
D4: 品川東急ビル3F
G6: 発送番号 | K6: 発送日 | N6: ページ
G7: 87482297 | K7: 45405 | N7: 1の1
D8: 登録番号: T2010401090562 | G8: 発送業者 | L8: B/L
G9: 佐川急便
D11: 請求番号 | F11: 請求日 | J11: 注文番号
D12: 3003877451 | F12: 04/23/2024
D13: 受注番号 | F13: 配送条件 | J13: 貿易取引条件
D14: 0022047564 | F14: 元払い
D15: 出荷先: | I15: 請求先: | K15: OT91990
D16: 山之内雄一 | I16: 山之内雄一
D17: 1130033 東京都 文京区 | I17: 1130033 東京都 文京区
D18: 本郷2-25-14 | I18: 本郷2-25-14
D19: 第一ライトビル５階４号室 | I19: 日本国
D20: 日本国
A22: № | B22: 製品型番 | F22: 数量 | H22: 単位 | J22: 商品単価 | M22: 商品金額
B23: 製品詳細
A24: 1 | B24: SDSQQNR-032G-GH3IA | G24: 1 | H24: EA | J24: 円 | L24: 1200 | O24: 1200
C25: SDSQQNR-032G-GH3IA,High Endurance uSD,10
B45: 支払い方法:
B46: Mastercard
H49: 税率（％）: 10 | K49: 円 | L49: 小計: | O49: =SUM(O24:O45) -> 1200
L50: 割引額: | O50: 0
L51: 配送料: | O51: 0
H52: 税率（％）: 10 | L52: 消費税額: | O52: =O49*10% -> 120
K53: 円 | L53: 合計: | O53: =O49+O52 -> 1320
A58: お買い上げいただきありがとうございました。

Sheet 1_1_請求書兼領収書 ウエスタンデジタル
D2: ウエスタンデジタル合同会社 | K2: 請求書 兼 領収書
D3: 〒108-0075 東京都港区港南1-6-31 | S3: 番号
D4: 品川東急ビル3F | R4: 仕入れ元
R5: 仕入れ先
G6: 発送番号 | J6: 発送日 | M6: ページ
G7: 87482297 | J7: 45405 | M7: 1の1
D8: 登録番号: T2010401090562 | G8: 発送業者 | K8: B/L | R8: № | U8: 型番 | W8: JANコード
G9: 佐川急便 | R9: 1 | S9: 63 | T9: 型番： | U9: SDSQUAB-064G-GN6MN | V9: JANコード： | W9: 619659200473
R10: 2 | S10: 90 | T10: 型番： | U10: SDSQUAB-128G-GN6MN | V10: JANコード： | W10: 619659200480
D11: 請求番号 | F11: 請求日 | J11: 注文番号 | R11: 3 | S11: 115 | T11: 型番： | U11: SDSQUAC-256G-GN6MN | V11: JANコード： | W11: 619659200497
D12: 3003877451 | F12: =J7 -> 45405 | R12: 4 | S12: 138 | T12: 型番： | U12: SDSQUAC-512G-GN6MN | V12: JANコード： | W12: 619659200503
D13: 受注番号 | F13: 配送条件 | J13: 貿易取引条件 | R13: 5 | S13: 168 | T13: 型番： | U13: SDSQXAF-032G-GN6MN | V13: JANコード： | W13: 619659177416
D14: S0022047564 | F14: 元払い | R14: 6 | S14: 180 | T14: 型番： | U14: SDSQXA2-064G-GN6MA | V14: JANコード： | W14: 619659169770
D15: 出荷先: | E15: OT91990 | I15: 請求先: | J15: =E15 -> OT91990 | R15: 7 | S15: 199 | T15: 型番： | U15: SDSQXA1-128G-GN6MN | V15: JANコード： | W15: 619659180034
D16: 東映無線株式会社 | I16: =D16 -> 東映無線株式会社 | R16: 8 | S16: 214 | T16: 型番： | U16: SDSQXA1-256G-GN6MN | V16: JANコード： | W16: 619659180041
D17: 101-0021 東京都千代田区 | I17: =D17 -> 101-0021 東京都千代田区 | R17: 9 | S17: 195 | T17: 型番： | U17: SDSQXAH-064G-GN6MN | V17: JANコード： | W17: 619659193416
D18: 外神田1丁目10番11号 | I18: =D18 -> 外神田1丁目10番11号 | R18: 10 | S18: 198 | T18: 型番： | U18: SDSQXAA-128G-GN6MN | V18: JANコード： | W18: 619659188467
D19: 東京ラジオデパート | I19: =D19 -> 東京ラジオデパート | R19: 11 | S19: 213 | T19: 型番： | U19: SDSQXAV-256G-GN6MN | V19: JANコード： | W19: 619659188511
D20: 日本国 | I20: =D20 -> 日本国 | R20: 12 | S20: 230 | T20: 型番： | U20: SDSQXAV-512G-GN6MN | V20: JANコード： | W20: 619659189655
R21: 13 | S21: 330 | T21: 型番： | U21: SDSDUNB-064G-GH3NN | V21: JANコード： | W21: 619659200671
R22: 14 | S22: 340 | T22: 型番： | U22: SDSDUNB-128G-GH3NN | V22: JANコード： | W22: 619659200107
R23: 15 | S23: 350 | T23: 型番： | U23: SDSDUNC-256G-GH3NN | V23: JANコード： | W23: 619659200701
A24: № | R24: 16 | S24: 390 | T24: 型番： | U24: SDSDXXO-032G-GN4IN | V24: JANコード： | W24: 619659188689
A26: 1 | B26: =T9&U9&" "&V9&W9 -> 型番：SDSQUAB-064G-GN6MN JANコード：619659200473 | G26: 1 | H26: EA | I26: 円 | K26: 0 | N26: =K26*G26 -> 0
A28: 2 | B28: =T10&U10&" "&V10&W10 -> 型番：SDSQUAB-128G-GN6MN JANコード：619659200480 | G28: 2 | H28: EA | I28: 円 | K28: 55 | N28: =K28*G28 -> 110
B29: UHS-I / U1 / A1 / C10 /
A30: 3 | B30: =T11&U11&" "&V11&W11 -> 型番：SDSQUAC-256G-GN6MN JANコード：619659200497 | G30: 3 | H30: EA | I30: 円 | K30: 0 | N30: =K30*G30 -> 0
A32: 4 | B32: =T12&U12&" "&V12&W12 -> 型番：SDSQUAC-512G-GN6MN JANコード：619659200503 | G32: 4 | H32: EA | I32: 円 | K32: 0 | N32: =K32*G32 -> 0
B33: UHS-I / Nintendo Switch /
A34: 5 | B34: =T13&U13&" "&V13&W13 -> 型番：SDSQXAF-032G-GN6MN JANコード：619659177416 | G34: 5 | H34: EA | I34: 円 | K34: 0 | N34: =K34*G34 -> 0
B35: U3 / Class10 /
A36: 6 | B36: =T14&U14&" "&V14&W14 -> 型番：SDSQXA2-064G-GN6MA JANコード：619659169770 | G36: 6 | H36: EA | I36: 円 | K36: 0 | N36: =K36*G36 -> 0
A38: 7 | B38: =T15&U15&" "&V15&W15 -> 型番：SDSQXA1-128G-GN6MN JANコード：619659180034 | G38: 7 | H38: EA | I38: 円 | K38: 0 | N38: =K38*G38 -> 0
B39: U3 / V30 / 4K /
A40: 8 | B40: =T16&U16&" "&V16&W16 -> 型番：SDSQXA1-256G-GN6MN JANコード：619659180041 | G40: 8 | H40: EA | I40: 円 | K40: 0 | N40: =K40*G40 -> 0
B41: U3 / V30 / A1 / 4K /
A42: 9 | B42: =T17&U17&" "&V17&W17 -> 型番：SDSQXAH-064G-GN6MN JANコード：619659193416 | G42: 9 | H42: EA | I42: 円 | K42: 100 | N42: =K42*G42 -> 900
B43: 4K /
A44: 10 | B44: =T18&U18&" "&V18&W18 -> 型番：SDSQXAA-128G-GN6MN JANコード：619659188467 | G44: 11 | H44: EA | I44: 円 | K44: 125 | N44: =K44*G44 -> 1375
B45: UHS-I / U3 / V30 / 4K /
...

Sheet 1_1_納品書ウエスタンデジタル
G2: Page | H2: 1 of 1
C3: 納品書 | I3: ウエスタンデジタル合同会社
I4: 東京都港区港南1-6-31
I5: 品川東急ビル3F
I6: カスタマーサービス電話番号：0066-3381-4967
A7: 注文番号： | C7: 配送番号： | D7: 90259161
A8: お名前： | B8: 東映無線株式会社 | E8: 日付： | F8: 45405
A9: 住所： | B9: 外神田1丁目10番11号 | E9: 連絡先：
B10: 東京ラジオデパート | E10: 電話番号： | F10: 03-32535660
B11: 〒101-0021
B12: JAPAN
A14: 製品名 | G14: 数量
A15: 型番：SDSQUAB-064G-GN6MN JANコード：619659200473 | G15: 1
A16: 型番：SDSQUAB-128G-GN6MN JANコード：619659200480 | G16: 2
A17: 型番：SDSQUAC-256G-GN6MN JANコード：619659200497 | G17: 3
A18: 型番：SDSQUAC-512G-GN6MN JANコード：619659200503 | G18: 4
A19: 型番：SDSQXAF-032G-GN6MN JANコード：619659177416 | G19: 5
A20: 型番：SDSQXA2-064G-GN6MA JANコード：619659169770 | G20: 6
A21: 型番：SDSQXA1-128G-GN6MN JANコード：619659180034 | G21: 7
A22: 型番：SDSQXA1-256G-GN6MN JANコード：619659180041 | G22: 8
A23: 型番：SDSQXAH-064G-GN6MN JANコード：619659193416 | G23: 9
A24: 型番：SDSQXAA-128G-GN6MN JANコード：619659188467 | G24: 11
A25: 型番：SDSQXAV-256G-GN6MN JANコード：619659188511 | G25: 12
A26: 型番：SDSQXAV-512G-GN6MN JANコード：619659189655 | G26: 13
... A30: 型番：SDSDXXO-032G-GN4IN JANコード：619659188689 | G30: 17
F31: 合計： | G31: =SUM(G15:I30) -> 143
A33: この度はサンディスクストアにて商品をお買い上げいただき誠にありがとうございます。
A34: 商品を送付させていただきます。今後ともご愛顧賜りますよう何卒よろしくお願い申し上げます。

Sheet 1_2_請求書兼領収書 ウエスタンデジタル線引き
E2: ウエスタンデジタル合同会社 | L2: 請求書 兼 領収書
E3: 〒108-0075 東京都港区港南1-6-31 | T3: アカウント
E4: 品川東急ビル3F | S4: 番号 | T4: 105
H6: 発送番号 | K6: 発送日 | N6: ページ
H7: 87482297 | K7: 45762 | N7: 1の1
E8: 登録番号: T2010401090562 | H8: 発送業者 | L8: B/L | S8: № | V8: 型番 | X8: JANコード
H9: 佐川急便 | S9: 1 | T9: 89 | U9: 型番： | V9: SDSQUAB-128G-GH3MA | W9: コード： | X9: 619659201579 | Y9: SanDisk
S10: 2 | T10: 114 | U10: 型番： | V10: SDSQUAC-256G-GH3MA | W10: コード： | X10: 619659201555 | Y10: SanDisk
E11: 請求番号 | G11: 請求日 | K11: 注文番号 | S11: 3 | T11: 167 | U11: 型番： | V11: SDSQXAT-032G-GH3MA | W11: コード： | X11: 619659197940 | Y11: SanDisk
E12: 3003877451 | G12: =K7 -> 45762 | S12: 4 | T12: 179 | U12: 型番： | V12: SDSQXAH-064G-GH3MA | W12: コード： | X12: 619659197933 | Y12: SanDisk
E13: 受注番号 | G13: 配送条件 | K13: 貿易取引条件 | S13: 5 | T13: 197 | U13: 型番： | V13: SDSQXAA-128G-GH3MA | W13: コード： | X13: 619659197926 | Y13: SanDisk
E14: S0022047564 | G14: 元払い | S14: 6 | T14: 212 | U14: 型番： | V14: SDSQXAV-256G-GH3MA | W14: コード： | X14: 619659197964 | Y14: SanDisk
E15: 出荷先: | F15: OT91990 | J15: 請求先: | K15: =F15 -> OT91990 | S15: 7 | T15: 287 | U15: 型番： | V15: SDSQQNR-032G-GH3IA | W15: コード： | X15: 619659197704 | Y15: SanDisk
E16: 東映無線株式会社 | J16: =E16 -> 東映無線株式会社 | S16: 8 | T16: 292 | U16: 型番： | V16: SDSQQNR-064G-GH3IA | W16: コード： | X16: 619659197711 | Y16: SanDisk
E17: 101-0021 東京都千代田区 | J17: =E17 -> 101-0021 東京都千代田区 | S17: 9 | T17: 297 | U17: 型番： | V17: SDSQQNR-128G-GH3IA | W17: コード： | X17: 619659198923 | Y17: SanDisk
E18: 外神田1丁目10番11号 | J18: =E18 -> 外神田1丁目10番11号 | S18: 10 | T18: 302 | U18: 型番： | V18: SDSQQNR-256G-GH3IA | W18: コード： | X18: 619659198930 | Y18: SanDisk
E19: 東京ラジオデパート | J19: =E19 -> 東京ラジオデパート | S19: 11 | T19: 365 | U19: 型番： | V19: SDSDXV2-064G-GHJIN | W19: コード： | X19: 619659197834 | Y19: SanDisk
E20: 日本国 | J20: =E20 -> 日本国 | S20: 12 | T20: 373 | U20: 型番： | V20: SDSDXVA-128G-GHJIN | W20: コード： | X20: 619659197841 | Y20: SanDisk
S21: 13 | T21: 380 | U21: 型番： | V21: SDSDXVV-256G-GHJIN | W21: コード： | X21: 619659197858 | Y21: SanDisk
S22: 14 | T22: 407 | U22: 型番： | V22: SDSDXXD-128G-GHJIN | W22: コード： | X22: 619659197889 | Y22: SanDisk
S23: 15 | T23: 419 | U23: 型番： | V23: SDSDXXD-256G-GHJIN | W23: コード： | X23: 619659197896 | Y23: SanDisk
A24: No. | B24: 製品型番 | G24: 数量 | I24: 単価 | J24: 商品単価 | M24: 商品金額 | S24: 16 | T24: 434 | U24: 型番： | V24: SDSDXEP-064G-GHJIN | W24: コード： | X24: 619659201494 | Y24: SanDisk
B25: 製品詳細 | S25: 17 | T25: 437 | U25: 型番： | V25: SDSDXEP-128G-GHJIN | W25: コード： | X25: 619659201500 | Y25: SanDisk
A26: 1 | B26: =Y9&" "&W9&X9&" "&U9&V9 -> SanDisk コード：619659201579 型番：SDSQUAB-128G-GH3MA | H26: 150 | I26: EA | J26: 円 | L26: 70 | O26: =L26*H26 -> 10500 | S26: 18 | T26: 180 | U26: 型番： | V26: SDSQXA2-064G-GN6MA | W26: コード： | X26: 619659169770 | Y26: SanDisk
A27: 2 | B27: =Y10&" "&W10&X10&" "&U10&V10 -> SanDisk コード：619659201555 型番：SDSQUAC-256G-GH3MA | H27: 550 | I27: EA | J27: 円 | L27: 0 | O27: =L27*H27 -> 0 | S27: 19 | T27: 199 | U27: 型番： | V27: SDSQXA1-128G-GN6MN | W27: コード： | X27: 619659180034 | Y27: SanDisk
A28: 3 | B28: =Y11&" "&W11&X11&" "&U11&V11 -> SanDisk コード：619659197940 型番：SDSQXAT-032G-GH3MA | H28: 50 | I28: EA | J28: 円 | L28: 0 | O28: =L28*H28 -> 0 | S28: 20 | T28: 214 | U28: 型番： | V28: SDSQXA1-256G-GN6MN | W28: コード： | X28: 619659180041 | Y28: SanDisk
A29: 4 | B29: =Y12&" "&W12&X12&" "&U12&V12 -> SanDisk コード：619659197933 型番：SDSQXAH-064G-GH3MA | H29: 80 | I29: EA | J29: 円 | L29: 60 | O29: =L29*H29 -> 4800 | S29: 21 | T29: 168 | U29: 型番： | V29: SDSQXAF-032G-GN6MN | W29: コード： | X29: 619659177416 | Y29: SanDisk
A30: 5 | B30: =Y13&" "&W13&X13&" "&U13&V13 -> SanDisk コード：619659197926 型番：SDSQXAA-128G-GH3MA | H30: 150 | I30: EA | J30: 円 | L30: 150 | O30: =L30*H30 -> 22500 | S30: 22 | T30: 195 | U30: 型番： | V30: SDSQXAH-064G-GN6MN | W30: コード： | X30: 619659193416 | Y30: SanDisk
A31: 6 | B31: =Y14&" "&W14&X14&" "&U14&V14 -> SanDisk コード：619659197964 型番：SDSQXAV-256G-GH3MA | H31: 70 | I31: EA | J31: 円 | L31: 35 | O31: =L31*H31 -> 2450 | S31: 23 | T31: 198 | U31: 型番： | V31: SDSQXAA-128G-GN6MN | W31: コード： | X31: 619659188467 | Y31: SanDisk
A32: 7 | B32: =Y15&" "&W15&X15&" "&U15&V15 -> SanDisk コード：619659197704 型番：SDSQQNR-032G-GH3IA | H32: 35 | I32: EA | J32: 円 | L32: 0 | O32: =L32*H32 -> 0 | S32: 24 | T32: 213 | U32: 型番： | V32: SDSQXAV-256G-GN6MN | W32: コード： | X32: 619659188511 | Y32: SanDisk
A33: 8 | B33: =Y16&" "&W16&X16&" "&U16&V16 -> SanDisk コード：619659197711 型番：SDSQQNR-064G-GH3IA | H33: 40 | I33: EA | J33: 円 | L33: 0 | O33: =L33*H33 -> 0 | S33: 25 | T33: 63 | U33: 型番： | V33: SDSQUAB-064G-GN6MN | W33: コード： | X33: 619659200473 | Y33: SanDisk
A34: 9 | B34: =Y17&" "&W17&X17&" "&U17&V17 -> SanDisk コード：619659198923 型番：SDSQQNR-128G-GH3IA | H34: 70 | I34: EA | J34: 円 | L34: 0 | O34: =L34*H34 -> 0 | S34: 26 | T34: 90 | U34: 型番： | V34: SDSQUAB-128G-GN6MN | W34: コード： | X34: 619659200480 | Y34: SanDisk
A35: 10 | B35: =Y18&" "&W18&X18&" "&U18&V18 -> SanDisk コード：619659198930 型番：SDSQQNR-256G-GH3IA | H35: 25 | I35: EA | J35: 円 | L35: 0 | O35: =L35*H35 -> 0 | S35: 27 | T35: 115 | U35: 型番： | V35: SDSQUAC-256G-GN6MN | W35: コード： | X35: 619659200497 | Y35: SanDisk
A36: 11 | B36: =Y19&" "&W19&X19&" "&U19&V19 -> SanDisk コード：619659197834 型番：SDSDXV2-064G-GHJIN | H36: 50 | I36: EA | J36: 円 | L36: 0 | O36: =L36*H36 -> 0 | S36: 28 | U36: 型番： | V36: #N/A | W36: コード： | X36: #N/A | Y36: SanDisk
A37: 12 | B37: =Y20&" "&W20&X20&" "&U20&V20 -> SanDisk コード：619659197841 型番：SDSDXVA-128G-GHJIN | H37: 650 | I37: EA | J37: 円 | L37: 50 | O37: =L37*H37 -> 32500 | S37: 29 | U37: 型番： | V37: #N/A | W37: コード： | X37: #N/A | Y37: SanDisk
A38: 13 | B38: =Y21&" "&W21&X21&" "&U21&V21 -> SanDisk コード：619659197858 型番：SDSDXVV-256G-GHJIN | H38: 250 | I38: EA | J38: 円 | L38: 0 | O38: =L38*H38 -> 0 | S38: 30 | U38: 型番： | V38: #N/A | W38: コード： | X38: #N/A | Y38: SanDisk
A39: 14 | B39: =Y22&" "&W22&X22&" "&U22&V22 -> SanDisk コード：619659197889 型番：SDSDXXD-128G-GHJIN | H39: 350 | I39: EA | J39: 円 | L39: 0 | O39: =L39*H39 -> 0
A40: 15 | B40: =Y23&" "&W23&X23&" "&U23&V23 -> SanDisk コード：619659197896 型番：SDSDXXD-256G-GHJIN | H40: 100 | I40: EA | J40: 円 | L40: 0 | O40: =L40*H40 -> 0
A41: 16 | B41: =Y24&" "&W24&X24&" "&U24&V24 -> SanDisk コード：619659201494 型番：SDSDXEP-064G-GHJIN | H41: 20 | I41: EA | J41: 円 | L41: 0 | O41: =L41*H41 -> 0
A42: 17 | B42: =Y25&" "&W25&X25&" "&U25&V25 -> SanDisk コード：619659201500 型番：SDSDXEP-128G-GHJIN | H42: 15 | I42: EA | J42: 円 | L42: 9999 | O42: =L42*H42 -> 149985
...

Sheet 1_2_請求書兼領収書 ウエスタンデジタル
E2: ウエスタンデジタル合同会社 | L2: 請求書 兼 領収書
E3: 〒108-0075 東京都港区港南1-6-31 | T3: 番号
E4: 品川東急ビル3F | S4: 仕入れ元
S5: 仕入れ先
H6: 発送番号 | K6: 発送日 | N6: ページ
H7: 87482297 | K7: 45762 | N7: 1の1
E8: 登録番号: T2010401090562 | H8: 発送業者 | L8: B/L | S8: № | V8: 型番 | X8: JANコード
H9: 佐川急便 | S9: 1 | T9: 89 | U9: 型番： | V9: SDSQUAB-128G-GH3MA | W9: コード： | X9: 619659201579 | Y9: SanDisk
S10: 2 | T10: 114 | U10: 型番： | V10: SDSQUAC-256G-GH3MA | W10: コード： | X10: 619659201555 | Y10: SanDisk
E11: 請求番号 | G11: 請求日 | K11: 注文番号 | S11: 3 | T11: 167 | U11: 型番： | V11: SDSQXAT-032G-GH3MA | W11: コード： | X11: 619659197940 | Y11: SanDisk
E12: 3003877451 | G12: =K7 -> 45762 | S12: 4 | T12: 179 | U12: 型番： | V12: SDSQXAH-064G-GH3MA | W12: コード： | X12: 619659197933 | Y12: SanDisk
E13: 受注番号 | G13: 配送条件 | K13: 貿易取引条件 | S13: 5 | T13: 197 | U13: 型番： | V13: SDSQXAA-128G-GH3MA | W13: コード： | X13: 619659197926 | Y13: SanDisk
E14: S0022047564 | G14: 元払い | S14: 6 | T14: 212 | U14: 型番： | V14: SDSQXAV-256G-GH3MA | W14: コード： | X14: 619659197964 | Y14: SanDisk
E15: 出荷先: | F15: OT91990 | J15: 請求先: | K15: =F15 -> OT91990 | S15: 7 | T15: 287 | U15: 型番： | V15: SDSQQNR-032G-GH3IA | W15: コード： | X15: 619659197704 | Y15: SanDisk
E16: 東映無線株式会社 | J16: =E16 -> 東映無線株式会社 | S16: 8 | T16: 292 | U16: 型番： | V16: SDSQQNR-064G-GH3IA | W16: コード： | X16: 619659197711 | Y16: SanDisk
E17: 101-0021 東京都千代田区 | J17: =E17 -> 101-0021 東京都千代田区 | S17: 9 | T17: 297 | U17: 型番： | V17: SDSQQNR-128G-GH3IA | W17: コード： | X17: 619659198923 | Y17: SanDisk
E18: 外神田1丁目10番11号 | J18: =E18 -> 外神田1丁目10番11号 | S18: 10 | T18: 302 | U18: 型番： | V18: SDSQQNR-256G-GH3IA | W18: コード： | X18: 619659198930 | Y18: SanDisk
E19: 東京ラジオデパート | J19: =E19 -> 東京ラジオデパート | S19: 11 | T19: 365 | U19: 型番： | V19: SDSDXV2-064G-GHJIN | W19: コード： | X19: 619659197834 | Y19: SanDisk
E20: 日本国 | J20: =E20 -> 日本国 | S20: 12 | T20: 373 | U20: 型番： | V20: SDSDXVA-128G-GHJIN | W20: コード： | X20: 619659197841 | Y20: SanDisk
S21: 13 | T21: 380 | U21: 型番： | V21: SDSDXVV-256G-GHJIN | W21: コード： | X21: 619659197858 | Y21: SanDisk
S22: 14 | T22: 407 | U22: 型番： | V22: SDSDXXD-128G-GHJIN | W22: コード： | X22: 619659197889 | Y22: SanDisk
S23: 15 | T23: 419 | U23: 型番： | V23: SDSDXXD-256G-GHJIN | W23: コード： | X23: 619659197896 | Y23: SanDisk
B24: № | S24: 16 | T24: 434 | U24: 型番： | V24: SDSDXEP-064G-GHJIN | W24: コード： | X24: 619659201494 | Y24: SanDisk
S25: 17 | T25: 437 | U25: 型番： | V25: SDSDXEP-128G-GHJIN | W25: コード： | X25: 619659201500 | Y25: SanDisk
B26: 1 | C26: =Y9&" "&W9&X9&" "&U9&V9 -> SanDisk コード：619659201579 型番：SDSQUAB-128G-GH3MA | H26: 150 | I26: EA | J26: 円 | L26: 70 | O26: =L26*H26 -> 10500 | S26: 18 | T26: 180 | U26: 型番： | V26: SDSQXA2-064G-GN6MA | W26: コード： | X26: 619659169770 | Y26: SanDisk
B27: 2 | C27: =Y10&" "&W10&X10&" "&U10&V10 -> SanDisk コード：619659201555 型番：SDSQUAC-256G-GH3MA | H27: 550 | I27: EA | J27: 円 | L27: 0 | O27: =L27*H27 -> 0 | S27: 19 | T27: 199 | U27: 型番： | V27: SDSQXA1-128G-GN6MN | W27: コード： | X27: 619659180034 | Y27: SanDisk
B28: 3 | C28: =Y11&" "&W11&X11&" "&U11&V11 -> SanDisk コード：619659197940 型番：SDSQXAT-032G-GH3MA | H28: 50 | I28: EA | J28: 円 | L28: 0 | O28: =L28*H28 -> 0 | S28: 20 | T28: 214 | U28: 型番： | V28: SDSQXA1-256G-GN6MN | W28: コード： | X28: 619659180041 | Y28: SanDisk
B29: 4 | C29: =Y12&" "&W12&X12&" "&U12&V12 -> SanDisk コード：619659197933 型番：SDSQXAH-064G-GH3MA | H29: 80 | I29: EA | J29: 円 | L29: 60 | O29: =L29*H29 -> 4800 | S29: 21 | T29: 168 | U29: 型番： | V29: SDSQXAF-032G-GN6MN | W29: コード： | X29: 619659177416 | Y29: SanDisk
B30: 5 | C30: =Y13&" "&W13&X13&" "&U13&V13 -> SanDisk コード：619659197926 型番：SDSQXAA-128G-GH3MA | H30: 150 | I30: EA | J30: 円 | L30: 150 | O30: =L30*H30 -> 22500 | S30: 22 | T30: 195 | U30: 型番： | V30: SDSQXAH-064G-GN6MN | W30: コード： | X30: 619659193416 | Y30: SanDisk
B31: 6 | C31: =Y14&" "&W14&X14&" "&U14&V14 -> SanDisk コード：619659197964 型番：SDSQXAV-256G-GH3MA | H31: 70 | I31: EA | J31: 円 | L31: 35 | O31: =L31*H31 -> 2450 | S31: 23 | T31: 198 | U31: 型番： | V31: SDSQXAA-128G-GN6MN | W31: コード： | X31: 619659188467 | Y31: SanDisk
B32: 7 | C32: =Y15&" "&W15&X15&" "&U15&V15 -> SanDisk コード：619659197704 型番：SDSQQNR-032G-GH3IA | H32: 35 | I32: EA | J32: 円 | L32: 0 | O32: =L32*H32 -> 0 | S32: 24 | T32: 213 | U32: 型番： | V32: SDSQXAV-256G-GN6MN | W32: コード： | X32: 619659188511 | Y32: SanDisk
B33: 8 | C33: =Y16&" "&W16&X16&" "&U16&V16 -> SanDisk コード：619659197711 型番：SDSQQNR-064G-GH3IA | H33: 40 | I33: EA | J33: 円 | L33: 0 | O33: =L33*H33 -> 0 | S33: 25 | T33: 63 | U33: 型番： | V33: SDSQUAB-064G-GN6MN | W33: コード： | X33: 619659200473 | Y33: SanDisk
B34: 9 | C34: =Y17&" "&W17&X17&" "&U17&V17 -> SanDisk コード：619659198923 型番：SDSQQNR-128G-GH3IA | H34: 70 | I34: EA | J34: 円 | L34: 0 | O34: =L34*H34 -> 0 | S34: 26 | T34: 90 | U34: 型番： | V34: SDSQUAB-128G-GN6MN | W34: コード： | X34: 619659200480 | Y34: SanDisk
B35: 10 | C35: =Y18&" "&W18&X18&" "&U18&V18 -> SanDisk コード：619659198930 型番：SDSQQNR-256G-GH3IA | H35: 25 | I35: EA | J35: 円 | L35: 0 | O35: =L35*H35 -> 0 | S35: 27 | T35: 115 | U35: 型番： | V35: SDSQUAC-256G-GN6MN | W35: コード： | X35: 619659200497 | Y35: SanDisk
B36: 11 | C36: =Y19&" "&W19&X19&" "&U19&V19 -> SanDisk コード：619659197834 型番：SDSDXV2-064G-GHJIN | H36: 50 | I36: EA | J36: 円 | L36: 0 | O36: =L36*H36 -> 0 | S36: 28 | U36: 型番： | V36: #N/A | W36: コード： | X36: #N/A | Y36: SanDisk
B37: 12 | C37: =Y20&" "&W20&X20&" "&U20&V20 -> SanDisk コード：619659197841 型番：SDSDXVA-128G-GHJIN | H37: 650 | I37: EA | J37: 円 | L37: 50 | O37: =L37*H37 -> 32500 | S37: 29 | U37: 型番： | V37: #N/A | W37: コード： | X37: #N/A | Y37: SanDisk
B38: 13 | C38: =Y21&" "&W21&X21&" "&U21&V21 -> SanDisk コード：619659197858 型番：SDSDXVV-256G-GHJIN | H38: 250 | I38: EA | J38: 円 | L38: 0 | O38: =L38*H38 -> 0 | S38: 30 | U38: 型番： | V38: #N/A | W38: コード： | X38: #N/A | Y38: SanDisk
B39: 14 | C39: =Y22&" "&W22&X22&" "&U22&V22 -> SanDisk コード：619659197889 型番：SDSDXXD-128G-GHJIN | H39: 350 | I39: EA | J39: 円 | L39: 0 | O39: =L39*H39 -> 0
B40: 15 | C40: =Y23&" "&W23&X23&" "&U23&V23 -> SanDisk コード：619659197896 型番：SDSDXXD-256G-GHJIN | H40: 100 | I40: EA | J40: 円 | L40: 0 | O40: =L40*H40 -> 0
B41: 16 | C41: =Y24&" "&W24&X24&" "&U24&V24 -> SanDisk コード：619659201494 型番：SDSDXEP-064G-GHJIN | H41: 20 | I41: EA | J41: 円 | L41: 0 | O41: =L41*H41 -> 0
...

Sheet 1_2_納品書ウエスタンデジタル 
G2: Page | H2: 1 of 1
C3: 納品書 | I3: ウエスタンデジタル合同会社
I4: 東京都港区港南1-6-31
I5: 品川東急ビル3F
I6: カスタマーサービス電話番号：0066-3381-4967
A7: 注文番号： | C7: 配送番号： | D7: 90259161
A8: お名前： | B8: ='1_2_請求書兼領収書 ウエスタンデジタル'!E16 -> 東映無線株式会社 | E8: 日付： | F8: ='1_2_請求書兼領収書 ウエスタンデジタル'!K7 -> 45762
A9: 住所： | B9: ='1_2_請求書兼領収書 ウエスタンデジタル'!E18 -> 外神田1丁目10番11号 | E9: 連絡先：
B10: ='1_2_請求書兼領収書 ウエスタンデジタル'!E19 -> 東京ラジオデパート | E10: 電話番号： | F10: 03-32535660
B11: ="〒"&LEFT('1_2_請求書兼領収書 ウエスタンデジタル'!E17,8) -> 〒101-0021
B12: JAPAN
A14: 製品名 | G14: 数量
A15: ='1_2_請求書兼領収書 ウエスタンデジタル'!C26 -> SanDisk コード：619659201579 型番：SDSQUAB-128G-GH3MA | G15: ='1_2_請求書兼領収書 ウエスタンデジタル'!H26 -> 150
A16: ='1_2_請求書兼領収書 ウエスタンデジタル'!C27 -> SanDisk コード：619659201555 型番：SDSQUAC-256G-GH3MA | G16: ='1_2_請求書兼領収書 ウエスタンデジタル'!H27 -> 550
A17: ='1_2_請求書兼領収書 ウエスタンデジタル'!C28 -> SanDisk コード：619659197940 型番：SDSQXAT-032G-GH3MA | G17: ='1_2_請求書兼領収書 ウエスタンデジタル'!H28 -> 50
A18: ='1_2_請求書兼領収書 ウエスタンデジタル'!C29 -> SanDisk コード：619659197933 型番：SDSQXAH-064G-GH3MA | G18: ='1_2_請求書兼領収書 ウエスタンデジタル'!H29 -> 80
A19: ='1_2_請求書兼領収書 ウエスタンデジタル'!C30 -> SanDisk コード：619659197926 型番：SDSQXAA-128G-GH3MA | G19: ='1_2_請求書兼領収書 ウエスタンデジタル'!H30 -> 150
A20: ='1_2_請求書兼領収書 ウエスタンデジタル'!C31 -> SanDisk コード：619659197964 型番：SDSQXAV-256G-GH3MA | G20: ='1_2_請求書兼領収書 ウエスタンデジタル'!H31 -> 70
A21: ='1_2_請求書兼領収書 ウエスタンデジタル'!C32 -> SanDisk コード：619659197704 型番：SDSQQNR-032G-GH3IA | G21: ='1_2_請求書兼領収書 ウエスタンデジタル'!H32 -> 35
A22: ='1_2_請求書兼領収書 ウエスタンデジタル'!C33 -> SanDisk コード：619659197711 型番：SDSQQNR-064G-GH3IA | G22: ='1_2_請求書兼領収書 ウエスタンデジタル'!H33 -> 40
A23: ='1_2_請求書兼領収書 ウエスタンデジタル'!C34 -> SanDisk コード：619659198923 型番：SDSQQNR-128G-GH3IA | G23: ='1_2_請求書兼領収書 ウエスタンデジタル'!H34 -> 70
A24: ='1_2_請求書兼領収書 ウエスタンデジタル'!C35 -> SanDisk コード：619659198930 型番：SDSQQNR-256G-GH3IA | G24: ='1_2_請求書兼領収書 ウエスタンデジタル'!H35 -> 25
A25: ='1_2_請求書兼領収書 ウエスタンデジタル'!C36 -> SanDisk コード：619659197834 型番：SDSDXV2-064G-GHJIN | G25: ='1_2_請求書兼領収書 ウエスタンデジタル'!H36 -> 50
A26: ='1_2_請求書兼領収書 ウエスタンデジタル'!C37 -> SanDisk コード：619659197841 型番：SDSDXVA-128G-GHJIN | G26: ='1_2_請求書兼領収書 ウエスタンデジタル'!H37 -> 650
... A44: ='1_2_請求書兼領収書 ウエスタンデジタル'!C55 -> 0 | G44: ='1_2_請求書兼領収書 ウエスタンデジタル'!H55 -> 0
F45: 合計： | G45: =SUM(G15:I44) -> 4655
A47: この度はサンディスクストアにて商品をお買い上げいただき誠にありがとうございます。
A48: 商品を送付させていただきます。今後ともご愛顧賜りますよう何卒よろしくお願い申し上げます。

Sheet 1_3_請求書兼領収書
D2: サンディスク合同会社 | K2: 請求書 兼 領収書
D3: 〒108-0075 東京都港区港南1-6-31
D4: 品川東急ビル3F
G6: 発送番号 | J6: 発送日 | M6: ページ
G7: 87482297 | J7: 45405 | M7: 1の1
D8: 登録番号: T2010401090562 | G8: 発送業者 | K8: B/L | R8: № | U8: 型番 | W8: JANコード
G9: 佐川急便 | R9: 1 | S9: 63 | T9: 型番： | U9: SDSQUAB-064G-GN6MN | V9: JANコード： | W9: 619659200473
R10: 2 | S10: 90 | T10: 型番： | U10: SDSQUAB-128G-GN6MN | V10: JANコード： | W10: 619659200480
D11: 請求番号 | F11: 請求日 | J11: 注文番号 | R11: 3 | S11: 115 | T11: 型番： | U11: SDSQUAC-256G-GN6MN | V11: JANコード： | W11: 619659200497
D12: 3003877451 | F12: =J7 -> 45405 | R12: 4 | S12: 138 | T12: 型番： | U12: SDSQUAC-512G-GN6MN | V12: JANコード： | W12: 619659200503
D13: 受注番号 | F13: 配送条件 | J13: 貿易取引条件 | R13: 5 | S13: 168 | T13: 型番： | U13: SDSQXAF-032G-GN6MN | V13: JANコード： | W13: 619659177416
D14: S0022047564 | F14: 元払い | R14: 6 | S14: 180 | T14: 型番： | U14: SDSQXA2-064G-GN6MA | V14: JANコード： | W14: 619659169770
D15: 出荷先: | E15: OT91990 | I15: 請求先: | J15: =E15 -> OT91990 | R15: 7 | S15: 199 | T15: 型番： | U15: SDSQXA1-128G-GN6MN | V15: JANコード： | W15: 619659180034
D16: 東映無線株式会社 | I16: =D16 -> 東映無線株式会社 | R16: 8 | S16: 214 | T16: 型番： | U16: SDSQXA1-256G-GN6MN | V16: JANコード： | W16: 619659180041
D17: 101-0021 東京都千代田区 | I17: =D17 -> 101-0021 東京都千代田区 | R17: 9 | S17: 195 | T17: 型番： | U17: SDSQXAH-064G-GN6MN | V17: JANコード： | W17: 619659193416
D18: 外神田1丁目10番11号 | I18: =D18 -> 外神田1丁目10番11号 | R18: 10 | S18: 198 | T18: 型番： | U18: SDSQXAA-128G-GN6MN | V18: JANコード： | W18: 619659188467
D19: 東京ラジオデパート | I19: =D19 -> 東京ラジオデパート | R19: 11 | S19: 213 | T19: 型番： | U19: SDSQXAV-256G-GN6MN | V19: JANコード： | W19: 619659188511
D20: 日本国 | I20: =D20 -> 日本国 | R20: 12 | S20: 230 | T20: 型番： | U20: SDSQXAV-512G-GN6MN | V20: JANコード： | W20: 619659189655
R21: 13 | S21: 330 | T21: 型番： | U21: SDSDUNB-064G-GH3NN | V21: JANコード： | W21: 619659200671
R22: 14 | S22: 340 | T22: 型番： | U22: SDSDUNB-128G-GH3NN | V22: JANコード： | W22: 619659200107
R23: 15 | S23: 350 | T23: 型番： | U23: SDSDUNC-256G-GH3NN | V23: JANコード： | W23: 619659200701
A24: № | R24: 16 | S24: 390 | T24: 型番： | U24: SDSDXXO-032G-GN4IN | V24: JANコード： | W24: 619659188689
A26: 1 | B26: =T9&U9&" "&V9&W9 -> 型番：SDSQUAB-064G-GN6MN JANコード：619659200473 | G26: 1 | H26: EA | I26: 円 | K26: 0 | N26: =K26*G26 -> 0
A28: 2 | B28: =T10&U10&" "&V10&W10 -> 型番：SDSQUAB-128G-GN6MN JANコード：619659200480 | G28: 2 | H28: EA | I28: 円 | K28: 55 | N28: =K28*G28 -> 110
B29: UHS-I / U1 / A1 / C10 /
A30: 3 | B30: =T11&U11&" "&V11&W11 -> 型番：SDSQUAC-256G-GN6MN JANコード：619659200497 | G30: 3 | H30: EA | I30: 円 | K30: 0 | N30: =K30*G30 -> 0
A32: 4 | B32: =T12&U12&" "&V12&W12 -> 型番：SDSQUAC-512G-GN6MN JANコード：619659200503 | G32: 4 | H32: EA | I32: 円 | K32: 0 | N32: =K32*G32 -> 0
B33: UHS-I / Nintendo Switch /
A34: 5 | B34: =T13&U13&" "&V13&W13 -> 型番：SDSQXAF-032G-GN6MN JANコード：619659177416 | G34: 5 | H34: EA | I34: 円 | K34: 0 | N34: =K34*G34 -> 0
B35: U3 / Class10 /
A36: 6 | B36: =T14&U14&" "&V14&W14 -> 型番：SDSQXA2-064G-GN6MA JANコード：619659169770 | G36: 6 | H36: EA | I36: 円 | K36: 0 | N36: =K36*G36 -> 0
A38: 7 | B38: =T15&U15&" "&V15&W15 -> 型番：SDSQXA1-128G-GN6MN JANコード：619659180034 | G38: 7 | H38: EA | I38: 円 | K38: 0 | N38: =K38*G38 -> 0
B39: U3 / V30 / 4K /
A40: 8 | B40: =T16&U16&" "&V16&W16 -> 型番：SDSQXA1-256G-GN6MN JANコード：619659180041 | G40: 8 | H40: EA | I40: 円 | K40: 0 | N40: =K40*G40 -> 0
B41: U3 / V30 / A1 / 4K /
A42: 9 | B42: =T17&U17&" "&V17&W17 -> 型番：SDSQXAH-064G-GN6MN JANコード：619659193416 | G42: 9 | H42: EA | I42: 円 | K42: 100 | N42: =K42*G42 -> 900
B43: 4K /
A44: 10 | B44: =T18&U18&" "&V18&W18 -> 型番：SDSQXAA-128G-GN6MN JANコード：619659188467 | G44: 11 | H44: EA | I44: 円 | K44: 125 | N44: =K44*G44 -> 1375
B45: UHS-I / U3 / V30 / 4K /
A46: 11 | B46: =T19&U19&" "&V19&W19 -> 型番：SDSQXAV-256G-GN6MN JANコード：619659188511 | G46: 12 | H46: EA | I46: 円 | K46: 40 | N46: =K46*G46 -> 480
...

Sheet 1_3_納品書 
G2: Page | H2: 1 of 1
C3: 納品書 | I3: サンディスク合同会社
I4: 東京都港区港南1-6-31
I5: 品川東急ビル3F
I6: カスタマーサービス電話番号：0120-893-009
A7: 注文番号： | C7: 配送番号： | D7: 90259161
A8: お名前： | B8: 東映無線株式会社 | E8: 日付： | F8: 45405
A9: 住所： | B9: 外神田1丁目10番11号 | E9: 連絡先：
B10: 東京ラジオデパート | E10: 電話番号： | F10: 03-32535660
B11: 〒101-0021
B12: JAPAN
A14: 製品名 | G14: 数量
A15: 型番：SDSQUAB-064G-GN6MN JANコード：619659200473 | G15: 1
A16: 型番：SDSQUAB-128G-GN6MN JANコード：619659200480 | G16: 2
A17: 型番：SDSQUAC-256G-GN6MN JANコード：619659200497 | G17: 3
A18: 型番：SDSQUAC-512G-GN6MN JANコード：619659200503 | G18: 4
A19: 型番：SDSQXAF-032G-GN6MN JANコード：619659177416 | G19: 5
A20: 型番：SDSQXA2-064G-GN6MA JANコード：619659169770 | G20: 6
A21: 型番：SDSQXA1-128G-GN6MN JANコード：619659180034 | G21: 7
A22: 型番：SDSQXA1-256G-GN6MN JANコード：619659180041 | G22: 8
A23: 型番：SDSQXAH-064G-GN6MN JANコード：619659193416 | G23: 9
A24: 型番：SDSQXAA-128G-GN6MN JANコード：619659188467 | G24: 11
A25: 型番：SDSQXAV-256G-GN6MN JANコード：619659188511 | G25: 12
A26: 型番：SDSQXAV-512G-GN6MN JANコード：619659189655 | G26: 13
... A30: 型番：SDSDXXO-032G-GN4IN JANコード：619659188689 | G30: 17
F31: 合計： | G31: =SUM(G15:I30) -> 143
A33: この度はサンディスクストアにて商品をお買い上げいただき誠にありがとうございます。
A34: 商品を送付させていただきます。今後ともご愛顧賜りますよう何卒よろしくお願い申し上げます。

Sheet 1_4_請求書兼領収書 ウエスタンデジタル　数式入り
E2: ウエスタンデジタル合同会社 | L2: 請求書 兼 領収書
E3: 〒108-0075 東京都港区港南1-6-31 | T3: アカウント
E4: 品川東急ビル3F | S4: 番号 | T4: 105
H6: 発送番号 | K6: 発送日 | N6: ページ
H7: 87482297 | K7: 45762 | N7: 1の1
E8: 登録番号: T2010401090562 | H8: 発送業者 | L8: B/L | S8: № | V8: 型番 | X8: JANコード
H9: 佐川急便 | S9: 1 | T9: 89 | U9: 型番： | V9: SDSQUAB-128G-GH3MA | W9: コード： | X9: 619659201579 | Y9: SanDisk
S10: 2 | T10: 114 | U10: 型番： | V10: SDSQUAC-256G-GH3MA | W10: コード： | X10: 619659201555 | Y10: SanDisk
E11: 請求番号 | G11: 請求日 | K11: 注文番号 | S11: 3 | T11: 167 | U11: 型番： | V11: SDSQXAT-032G-GH3MA | W11: コード： | X11: 619659197940 | Y11: SanDisk
E12: 3003877451 | G12: =K7 -> 45762 | S12: 4 | T12: 179 | U12: 型番： | V12: SDSQXAH-064G-GH3MA | W12: コード： | X12: 619659197933 | Y12: SanDisk
E13: 受注番号 | G13: 配送条件 | K13: 貿易取引条件 | S13: 5 | T13: 197 | U13: 型番： | V13: SDSQXAA-128G-GH3MA | W13: コード： | X13: 619659197926 | Y13: SanDisk
E14: S0022047564 | G14: 元払い | S14: 6 | T14: 212 | U14: 型番： | V14: SDSQXAV-256G-GH3MA | W14: コード： | X14: 619659197964 | Y14: SanDisk
E15: 出荷先: | F15: OT91990 | J15: 請求先: | K15: =F15 -> OT91990 | S15: 7 | T15: 287 | U15: 型番： | V15: SDSQQNR-032G-GH3IA | W15: コード： | X15: 619659197704 | Y15: SanDisk
E16: 東葛電子販売 | J16: =E16 -> 東葛電子販売 | S16: 8 | T16: 292 | U16: 型番： | V16: SDSQQNR-064G-GH3IA | W16: コード： | X16: 619659197711 | Y16: SanDisk
